2023-12-30 19:20:07 [INFO] Question: What was the price on 2023-12-12?
2023-12-30 19:20:07 [INFO] Running PandasAI with openai LLM...
2023-12-30 19:20:07 [INFO] Prompt ID: 7d9f0727-4521-4c12-8ab8-2ff9f437feb3
2023-12-30 19:20:07 [INFO] Executing Step 0: CacheLookup
2023-12-30 19:20:07 [INFO] Executing Step 1: PromptGeneration
2023-12-30 19:20:07 [INFO] Using prompt: <dataframe>
dfs[0]:22x6
Open,High,Low,Close,Adj Close,Volume
20194.099609375,20291.55078125,20183.69921875,20267.900390625,20267.900390625,265800
19976.55078125,20104.650390625,19956.30078125,20096.599609375,20096.599609375,236200
20108.5,20158.69921875,20015.849609375,20133.150390625,20133.150390625,486600
</dataframe>




Update this initial code:
```python
# TODO: import the required dependencies
import pandas as pd

# Write code here

# Declare result var: type (possible values "string", "number", "dataframe", "plot"). Examples: { "type": "string", "value": f"The highest salary is {highest_salary}." } or { "type": "number", "value": 125 } or { "type": "dataframe", "value": pd.DataFrame({...}) } or { "type": "plot", "value": "temp_chart.png" }
```

Q: What was the price on 2023-12-12?
Variable `dfs: list[pd.DataFrame]` is already declared.

At the end, declare "result" variable as a dictionary of type and value.



Generate python code and return full updated code:
2023-12-30 19:20:07 [INFO] Executing Step 2: CodeGenerator
2023-12-30 19:20:09 [INFO] HTTP Request: POST https://api.openai.com/v1/chat/completions "HTTP/1.1 200 OK"
2023-12-30 19:20:09 [INFO] Code generated:
            ```
            # TODO: import the required dependencies
import pandas as pd

# Write code here
date = "2023-12-12"
price = dfs[0][dfs[0].index == date]["Close"].values[0]

# Declare result var
result = {"type": "string", "value": f"The price on {date} was {price}."}
            ```
            
2023-12-30 19:20:09 [INFO] Executing Step 3: CachePopulation
2023-12-30 19:20:09 [INFO] Executing Step 4: CodeExecution
2023-12-30 19:20:09 [INFO] Saving charts to C:\Users\mram\OneDrive - Intel Corporation\Python\OpenAI\ChatFun\exports\charts\temp_chart.png
2023-12-30 19:20:09 [INFO] 
Code running:
```
date = '2023-12-12'
price = dfs[0][dfs[0].index == date]['Close'].values[0]
result = {'type': 'string', 'value': f'The price on {date} was {price}.'}
        ```
2023-12-30 19:20:09 [INFO] Executing Step 5: ResultValidation
2023-12-30 19:20:09 [INFO] Answer: {'type': 'string', 'value': 'The price on 2023-12-12 was 20906.400390625.'}
2023-12-30 19:20:09 [INFO] Executed in: 2.2208118438720703s
2023-12-30 19:20:09 [INFO] Executing Step 6: ResultParsing
2023-12-30 19:29:30 [INFO] Question: What was the price on 2023-12-12?
2023-12-30 19:29:30 [INFO] Running PandasAI with openai LLM...
2023-12-30 19:29:30 [INFO] Prompt ID: 885003d4-4afd-4b6c-b11c-d4096522a2c7
2023-12-30 19:29:30 [INFO] Executing Step 0: CacheLookup
2023-12-30 19:29:30 [INFO] Using cached response
2023-12-30 19:29:30 [INFO] Executing Step 1: PromptGeneration
2023-12-30 19:29:30 [INFO] Executing Step 2: CodeGenerator
2023-12-30 19:29:30 [INFO] Executing Step 3: CachePopulation
2023-12-30 19:29:30 [INFO] Executing Step 4: CodeExecution
2023-12-30 19:29:30 [INFO] Saving charts to C:\Users\mram\OneDrive - Intel Corporation\Python\OpenAI\ChatFun\exports\charts\temp_chart.png
2023-12-30 19:29:30 [INFO] 
Code running:
```
date = '2023-12-12'
price = dfs[0][dfs[0].index == date]['Close'].values[0]
result = {'type': 'string', 'value': f'The price on {date} was {price}.'}
        ```
2023-12-30 19:29:30 [INFO] Executing Step 5: ResultValidation
2023-12-30 19:29:30 [INFO] Answer: {'type': 'string', 'value': 'The price on 2023-12-12 was 20906.400390625.'}
2023-12-30 19:29:30 [INFO] Executed in: 0.031418561935424805s
2023-12-30 19:29:30 [INFO] Executing Step 6: ResultParsing
2023-12-30 19:30:34 [INFO] Question: What was the lowest price ?

2023-12-30 19:30:34 [INFO] Running PandasAI with openai LLM...
2023-12-30 19:30:34 [INFO] Prompt ID: 6f0c2ec7-9e65-4318-9958-dba612cf19f3
2023-12-30 19:30:34 [INFO] Executing Step 0: CacheLookup
2023-12-30 19:30:34 [INFO] Executing Step 1: PromptGeneration
2023-12-30 19:30:34 [INFO] Using prompt: <dataframe>
dfs[0]:22x6
Open,High,Low,Close,Adj Close,Volume
20108.5,20158.69921875,20015.849609375,20133.150390625,20133.150390625,486600
19976.55078125,20104.650390625,19956.30078125,20096.599609375,20096.599609375,236200
20194.099609375,20291.55078125,20183.69921875,20267.900390625,20267.900390625,265800
</dataframe>




Update this initial code:
```python
# TODO: import the required dependencies
import pandas as pd

# Write code here

# Declare result var: type (possible values "string", "number", "dataframe", "plot"). Examples: { "type": "string", "value": f"The highest salary is {highest_salary}." } or { "type": "number", "value": 125 } or { "type": "dataframe", "value": pd.DataFrame({...}) } or { "type": "plot", "value": "temp_chart.png" }
```

Q: What was the lowest price ?

Variable `dfs: list[pd.DataFrame]` is already declared.

At the end, declare "result" variable as a dictionary of type and value.



Generate python code and return full updated code:
2023-12-30 19:30:34 [INFO] Executing Step 2: CodeGenerator
2023-12-30 19:30:36 [INFO] HTTP Request: POST https://api.openai.com/v1/chat/completions "HTTP/1.1 200 OK"
2023-12-30 19:30:36 [INFO] Code generated:
            ```
            # TODO: import the required dependencies
import pandas as pd

# Write code here
lowest_price = dfs[0]['Low'].min()

# Declare result var
result = {
    "type": "number",
    "value": lowest_price
}
            ```
            
2023-12-30 19:30:36 [INFO] Executing Step 3: CachePopulation
2023-12-30 19:30:36 [INFO] Executing Step 4: CodeExecution
2023-12-30 19:30:36 [INFO] Saving charts to C:\Users\mram\OneDrive - Intel Corporation\Python\OpenAI\ChatFun\exports\charts\temp_chart.png
2023-12-30 19:30:36 [INFO] 
Code running:
```
lowest_price = dfs[0]['Low'].min()
result = {'type': 'number', 'value': lowest_price}
        ```
2023-12-30 19:30:36 [INFO] Executing Step 5: ResultValidation
2023-12-30 19:30:36 [INFO] Answer: {'type': 'number', 'value': 19956.30078125}
2023-12-30 19:30:36 [INFO] Executed in: 1.6310193538665771s
2023-12-30 19:30:36 [INFO] Executing Step 6: ResultParsing
2023-12-30 19:50:18 [INFO] Question: What was the price on 2023-12-12?
2023-12-30 19:50:18 [INFO] Running PandasAI with openai LLM...
2023-12-30 19:50:18 [INFO] Prompt ID: 383fb80f-376f-4a8b-81e0-910f977c6844
2023-12-30 19:50:18 [INFO] Executing Step 0: CacheLookup
2023-12-30 19:50:18 [INFO] Using cached response
2023-12-30 19:50:18 [INFO] Executing Step 1: PromptGeneration
2023-12-30 19:50:18 [INFO] Executing Step 2: CodeGenerator
2023-12-30 19:50:18 [INFO] Executing Step 3: CachePopulation
2023-12-30 19:50:18 [INFO] Executing Step 4: CodeExecution
2023-12-30 19:50:18 [INFO] Saving charts to C:\Users\mram\OneDrive - Intel Corporation\Python\OpenAI\ChatFun\exports\charts\temp_chart.png
2023-12-30 19:50:18 [INFO] 
Code running:
```
date = '2023-12-12'
price = dfs[0][dfs[0].index == date]['Close'].values[0]
result = {'type': 'string', 'value': f'The price on {date} was {price}.'}
        ```
2023-12-30 19:50:18 [INFO] Executing Step 5: ResultValidation
2023-12-30 19:50:18 [INFO] Answer: {'type': 'string', 'value': 'The price on 2023-12-12 was 44.040000915527344.'}
2023-12-30 19:50:18 [INFO] Executed in: 0.03945040702819824s
2023-12-30 19:50:18 [INFO] Executing Step 6: ResultParsing
2023-12-30 20:22:21 [INFO] Question: What was the price on 2023-12-12?
2023-12-30 20:22:21 [INFO] Running PandasAI with openai LLM...
2023-12-30 20:22:21 [INFO] Prompt ID: 7995636c-077a-4dac-a9ea-83b85d748572
2023-12-30 20:22:21 [INFO] Executing Step 0: CacheLookup
2023-12-30 20:22:21 [INFO] Using cached response
2023-12-30 20:22:21 [INFO] Executing Step 1: PromptGeneration
2023-12-30 20:22:21 [INFO] Executing Step 2: CodeGenerator
2023-12-30 20:22:21 [INFO] Executing Step 3: CachePopulation
2023-12-30 20:22:21 [INFO] Executing Step 4: CodeExecution
2023-12-30 20:22:21 [INFO] Saving charts to C:\Users\mram\OneDrive - Intel Corporation\Python\OpenAI\ChatFun\exports\charts\temp_chart.png
2023-12-30 20:22:21 [INFO] 
Code running:
```
date = '2023-12-12'
price = dfs[0][dfs[0].index == date]['Close'].values[0]
result = {'type': 'string', 'value': f'The price on {date} was {price}.'}
        ```
2023-12-30 20:22:21 [INFO] Executing Step 5: ResultValidation
2023-12-30 20:22:21 [INFO] Answer: {'type': 'string', 'value': 'The price on 2023-12-12 was 44.040000915527344.'}
2023-12-30 20:22:21 [INFO] Executed in: 0.03308510780334473s
2023-12-30 20:22:21 [INFO] Executing Step 6: ResultParsing
2023-12-30 20:47:01 [INFO] Question: What was the price on 2023-12-12?
2023-12-30 20:47:01 [INFO] Running PandasAI with openai LLM...
2023-12-30 20:47:01 [INFO] Prompt ID: 23a64e9f-f04e-4f25-aef8-dfbc90ea190a
2023-12-30 20:47:01 [INFO] Executing Step 0: CacheLookup
2023-12-30 20:47:01 [INFO] Using cached response
2023-12-30 20:47:01 [INFO] Executing Step 1: PromptGeneration
2023-12-30 20:47:01 [INFO] Executing Step 2: CodeGenerator
2023-12-30 20:47:01 [INFO] Executing Step 3: CachePopulation
2023-12-30 20:47:01 [INFO] Executing Step 4: CodeExecution
2023-12-30 20:47:01 [INFO] Saving charts to C:\Users\mram\OneDrive - Intel Corporation\Python\OpenAI\ChatFun\exports\charts\temp_chart.png
2023-12-30 20:47:01 [INFO] 
Code running:
```
date = '2023-12-12'
price = dfs[0][dfs[0].index == date]['Close'].values[0]
result = {'type': 'string', 'value': f'The price on {date} was {price}.'}
        ```
2023-12-30 20:47:01 [INFO] Executing Step 5: ResultValidation
2023-12-30 20:47:01 [INFO] Answer: {'type': 'string', 'value': 'The price on 2023-12-12 was 44.040000915527344.'}
2023-12-30 20:47:01 [INFO] Executed in: 0.02854776382446289s
2023-12-30 20:47:01 [INFO] Executing Step 6: ResultParsing
2023-12-30 20:47:11 [INFO] Question: What was the highest price
2023-12-30 20:47:11 [INFO] Running PandasAI with openai LLM...
2023-12-30 20:47:11 [INFO] Prompt ID: 719ff120-e040-4972-b8f1-6a491b21cb03
2023-12-30 20:47:11 [INFO] Executing Step 0: CacheLookup
2023-12-30 20:47:11 [INFO] Executing Step 1: PromptGeneration
2023-12-30 20:47:11 [INFO] Using prompt: <dataframe>
dfs[0]:21x6
Open,High,Low,Close,Adj Close,Volume
44.36000061035156,44.36000061035156,42.86000061035156,6007172760,6587657278,43922500
44.650001525878906,45.09000015258789,44.40999984741211,6795007264,2939182796,46263000
43.29999923706055,43.310001373291016,41.689998626708984,6113214189,3562148987,50417600
</dataframe>




Update this initial code:
```python
# TODO: import the required dependencies
import pandas as pd

# Write code here

# Declare result var: type (possible values "string", "number", "dataframe", "plot"). Examples: { "type": "string", "value": f"The highest salary is {highest_salary}." } or { "type": "number", "value": 125 } or { "type": "dataframe", "value": pd.DataFrame({...}) } or { "type": "plot", "value": "temp_chart.png" }
```

Q: What was the highest price
Variable `dfs: list[pd.DataFrame]` is already declared.

At the end, declare "result" variable as a dictionary of type and value.



Generate python code and return full updated code:
2023-12-30 20:47:11 [INFO] Executing Step 2: CodeGenerator
2023-12-30 20:47:11 [INFO] HTTP Request: POST https://api.openai.com/v1/chat/completions "HTTP/1.1 401 Unauthorized"
2023-12-30 20:47:11 [ERROR] Pipeline failed on step 2: Error code: 401 - {'error': {'message': 'Incorrect API key provided: sk-mZHzJ***************************************UfHB. You can find your API key at https://platform.openai.com/account/api-keys.', 'type': 'invalid_request_error', 'param': None, 'code': 'invalid_api_key'}}
2023-12-31 03:00:02 [ERROR] 
1 Failed download:
2023-12-31 03:00:02 [ERROR] ['INTC']: Exception('%ticker%: No price data found, symbol may be delisted (period=1mo)')
2023-12-31 10:15:31 [INFO] Question: What was the price on 2023-12-20?
2023-12-31 10:15:31 [INFO] Running PandasAI with openai LLM...
2023-12-31 10:15:31 [INFO] Prompt ID: 0edada51-70f5-4853-b74e-95fa9cd97d66
2023-12-31 10:15:31 [INFO] Executing Step 0: CacheLookup
2023-12-31 10:15:31 [INFO] Executing Step 1: PromptGeneration
2023-12-31 10:15:31 [INFO] Using prompt: <dataframe>
dfs[0]:21x6
Open,High,Low,Close,Adj Close,Volume
43.29999923706055,43.310001373291016,41.689998626708984,42.349998474121094,42.349998474121094,50417600
44.36000061035156,44.36000061035156,42.86000061035156,43.7400016784668,43.7400016784668,43922500
44.650001525878906,45.09000015258789,44.40999984741211,44.70000076293945,44.70000076293945,46263000
</dataframe>




Update this initial code:
```python
# TODO: import the required dependencies
import pandas as pd

# Write code here

# Declare result var: type (possible values "string", "number", "dataframe", "plot"). Examples: { "type": "string", "value": f"The highest salary is {highest_salary}." } or { "type": "number", "value": 125 } or { "type": "dataframe", "value": pd.DataFrame({...}) } or { "type": "plot", "value": "temp_chart.png" }
```

Q: What was the price on 2023-12-20?
Variable `dfs: list[pd.DataFrame]` is already declared.

At the end, declare "result" variable as a dictionary of type and value.



Generate python code and return full updated code:
2023-12-31 10:15:31 [INFO] Executing Step 2: CodeGenerator
2023-12-31 10:15:31 [INFO] HTTP Request: POST https://api.openai.com/v1/chat/completions "HTTP/1.1 401 Unauthorized"
2023-12-31 10:15:31 [ERROR] Pipeline failed on step 2: Error code: 401 - {'error': {'message': 'Incorrect API key provided: sk-mZHzJ***************************************UfHB. You can find your API key at https://platform.openai.com/account/api-keys.', 'type': 'invalid_request_error', 'param': None, 'code': 'invalid_api_key'}}
2023-12-31 10:18:01 [INFO] Question: What was the price on 2023-12-12?
2023-12-31 10:18:01 [INFO] Running PandasAI with openai LLM...
2023-12-31 10:18:01 [INFO] Prompt ID: e5032802-2ba1-4dec-8acb-5314b7a5117b
2023-12-31 10:18:01 [INFO] Executing Step 0: CacheLookup
2023-12-31 10:18:01 [INFO] Using cached response
2023-12-31 10:18:01 [INFO] Executing Step 1: PromptGeneration
2023-12-31 10:18:01 [INFO] Executing Step 2: CodeGenerator
2023-12-31 10:18:01 [INFO] Executing Step 3: CachePopulation
2023-12-31 10:18:01 [INFO] Executing Step 4: CodeExecution
2023-12-31 10:18:01 [INFO] Saving charts to C:\Users\mram\OneDrive - Intel Corporation\Python\OpenAI\ChatFun\exports\charts\temp_chart.png
2023-12-31 10:18:01 [INFO] 
Code running:
```
date = '2023-12-12'
price = dfs[0][dfs[0].index == date]['Close'].values[0]
result = {'type': 'string', 'value': f'The price on {date} was {price}.'}
        ```
2023-12-31 10:18:01 [INFO] Executing Step 5: ResultValidation
2023-12-31 10:18:01 [INFO] Answer: {'type': 'string', 'value': 'The price on 2023-12-12 was 16354.25.'}
2023-12-31 10:18:01 [INFO] Executed in: 0.05878138542175293s
2023-12-31 10:18:01 [INFO] Executing Step 6: ResultParsing
2023-12-31 10:18:19 [INFO] Question: What was the price on 2023-12-20?
2023-12-31 10:18:19 [INFO] Running PandasAI with openai LLM...
2023-12-31 10:18:19 [INFO] Prompt ID: 98c7737b-773b-4aa9-ae0b-7349a2936637
2023-12-31 10:18:19 [INFO] Executing Step 0: CacheLookup
2023-12-31 10:18:19 [INFO] Executing Step 1: PromptGeneration
2023-12-31 10:18:19 [INFO] Using prompt: <dataframe>
dfs[0]:21x6
Open,High,Low,Close,Adj Close,Volume
44.650001525878906,45.09000015258789,44.40999984741211,44.70000076293945,44.70000076293945,46263000
44.36000061035156,44.36000061035156,42.86000061035156,43.7400016784668,43.7400016784668,43922500
43.29999923706055,43.310001373291016,41.689998626708984,42.349998474121094,42.349998474121094,50417600
</dataframe>




Update this initial code:
```python
# TODO: import the required dependencies
import pandas as pd

# Write code here

# Declare result var: type (possible values "string", "number", "dataframe", "plot"). Examples: { "type": "string", "value": f"The highest salary is {highest_salary}." } or { "type": "number", "value": 125 } or { "type": "dataframe", "value": pd.DataFrame({...}) } or { "type": "plot", "value": "temp_chart.png" }
```

Q: What was the price on 2023-12-20?
Variable `dfs: list[pd.DataFrame]` is already declared.

At the end, declare "result" variable as a dictionary of type and value.



Generate python code and return full updated code:
2023-12-31 10:18:19 [INFO] Executing Step 2: CodeGenerator
2023-12-31 10:18:22 [INFO] HTTP Request: POST https://api.openai.com/v1/chat/completions "HTTP/1.1 200 OK"
2023-12-31 10:18:22 [INFO] Code generated:
            ```
            # TODO: import the required dependencies
import pandas as pd

# Write code here
price = dfs[0].loc['2023-12-20', 'Close']

# Declare result var
result = {
    "type": "number",
    "value": price
}
            ```
            
2023-12-31 10:18:22 [INFO] Executing Step 3: CachePopulation
2023-12-31 10:18:22 [INFO] Executing Step 4: CodeExecution
2023-12-31 10:18:22 [INFO] Saving charts to C:\Users\mram\OneDrive - Intel Corporation\Python\OpenAI\ChatFun\exports\charts\temp_chart.png
2023-12-31 10:18:22 [INFO] 
Code running:
```
price = dfs[0].loc['2023-12-20', 'Close']
result = {'type': 'number', 'value': price}
        ```
2023-12-31 10:18:22 [INFO] Executing Step 5: ResultValidation
2023-12-31 10:18:22 [INFO] Answer: {'type': 'number', 'value': 45.7599983215332}
2023-12-31 10:18:22 [INFO] Executed in: 2.6710383892059326s
2023-12-31 10:18:22 [INFO] Executing Step 6: ResultParsing
2023-12-31 10:39:11 [INFO] Question: What was the price on 2023-12-20?
2023-12-31 10:39:11 [INFO] Running PandasAI with openai LLM...
2023-12-31 10:39:11 [INFO] Prompt ID: b5c1d393-cfa3-43e7-a126-9dd0117cb6ae
2023-12-31 10:39:11 [INFO] Executing Step 0: CacheLookup
2023-12-31 10:39:11 [INFO] Using cached response
2023-12-31 10:39:11 [INFO] Executing Step 1: PromptGeneration
2023-12-31 10:39:11 [INFO] Executing Step 2: CodeGenerator
2023-12-31 10:39:11 [INFO] Executing Step 3: CachePopulation
2023-12-31 10:39:11 [INFO] Executing Step 4: CodeExecution
2023-12-31 10:39:11 [INFO] Saving charts to C:\Users\mram\OneDrive - Intel Corporation\Python\OpenAI\ChatFun\exports\charts\temp_chart.png
2023-12-31 10:39:11 [INFO] 
Code running:
```
price = dfs[0].loc['2023-12-20', 'Close']
result = {'type': 'number', 'value': price}
        ```
2023-12-31 10:39:11 [INFO] Executing Step 5: ResultValidation
2023-12-31 10:39:11 [INFO] Answer: {'type': 'number', 'value': 45.7599983215332}
2023-12-31 10:39:11 [INFO] Executed in: 0.029668331146240234s
2023-12-31 10:39:11 [INFO] Executing Step 6: ResultParsing
2023-12-31 10:39:26 [INFO] Question: What was the price on 2023-12-12?
2023-12-31 10:39:26 [INFO] Running PandasAI with openai LLM...
2023-12-31 10:39:26 [INFO] Prompt ID: 8635c005-2b72-44aa-89f0-c473949e1860
2023-12-31 10:39:26 [INFO] Executing Step 0: CacheLookup
2023-12-31 10:39:26 [INFO] Using cached response
2023-12-31 10:39:26 [INFO] Executing Step 1: PromptGeneration
2023-12-31 10:39:26 [INFO] Executing Step 2: CodeGenerator
2023-12-31 10:39:26 [INFO] Executing Step 3: CachePopulation
2023-12-31 10:39:26 [INFO] Executing Step 4: CodeExecution
2023-12-31 10:39:26 [INFO] Saving charts to C:\Users\mram\OneDrive - Intel Corporation\Python\OpenAI\ChatFun\exports\charts\temp_chart.png
2023-12-31 10:39:26 [INFO] 
Code running:
```
date = '2023-12-12'
price = dfs[0][dfs[0].index == date]['Close'].values[0]
result = {'type': 'string', 'value': f'The price on {date} was {price}.'}
        ```
2023-12-31 10:39:26 [INFO] Executing Step 5: ResultValidation
2023-12-31 10:39:26 [INFO] Answer: {'type': 'string', 'value': 'The price on 2023-12-12 was 16354.25.'}
2023-12-31 10:39:26 [INFO] Executed in: 0.03241920471191406s
2023-12-31 10:39:26 [INFO] Executing Step 6: ResultParsing
2023-12-31 10:39:37 [INFO] Question: What was the price on 2023-12-12?
2023-12-31 10:39:37 [INFO] Running PandasAI with openai LLM...
2023-12-31 10:39:37 [INFO] Prompt ID: 5b1f8d76-5905-4b66-a186-afa05005ba0f
2023-12-31 10:39:37 [INFO] Executing Step 0: CacheLookup
2023-12-31 10:39:37 [INFO] Using cached response
2023-12-31 10:39:37 [INFO] Executing Step 1: PromptGeneration
2023-12-31 10:39:37 [INFO] Executing Step 2: CodeGenerator
2023-12-31 10:39:37 [INFO] Executing Step 3: CachePopulation
2023-12-31 10:39:37 [INFO] Executing Step 4: CodeExecution
2023-12-31 10:39:37 [INFO] Saving charts to C:\Users\mram\OneDrive - Intel Corporation\Python\OpenAI\ChatFun\exports\charts\temp_chart.png
2023-12-31 10:39:37 [INFO] 
Code running:
```
date = '2023-12-12'
price = dfs[0][dfs[0].index == date]['Close'].values[0]
result = {'type': 'string', 'value': f'The price on {date} was {price}.'}
        ```
2023-12-31 10:39:37 [INFO] Executing Step 5: ResultValidation
2023-12-31 10:39:37 [INFO] Answer: {'type': 'string', 'value': 'The price on 2023-12-12 was 44.040000915527344.'}
2023-12-31 10:39:37 [INFO] Executed in: 0.026778697967529297s
2023-12-31 10:39:37 [INFO] Executing Step 6: ResultParsing
2023-12-31 10:40:20 [INFO] Question: What was the value of shares traded on 2023-12-12?
2023-12-31 10:40:20 [INFO] Running PandasAI with openai LLM...
2023-12-31 10:40:20 [INFO] Prompt ID: 6d5e217c-d3a5-49dd-9448-c001e053531c
2023-12-31 10:40:20 [INFO] Executing Step 0: CacheLookup
2023-12-31 10:40:20 [INFO] Executing Step 1: PromptGeneration
2023-12-31 10:40:20 [INFO] Using prompt: <dataframe>
dfs[0]:21x6
Open,High,Low,Close,Adj Close,Volume
44.36000061035156,44.36000061035156,42.86000061035156,0449655285,5286597605,43922500
43.29999923706055,43.310001373291016,41.689998626708984,7263663117,8857368614,50417600
44.650001525878906,45.09000015258789,44.40999984741211,9938797414,2128671383,46263000
</dataframe>




Update this initial code:
```python
# TODO: import the required dependencies
import pandas as pd

# Write code here

# Declare result var: type (possible values "string", "number", "dataframe", "plot"). Examples: { "type": "string", "value": f"The highest salary is {highest_salary}." } or { "type": "number", "value": 125 } or { "type": "dataframe", "value": pd.DataFrame({...}) } or { "type": "plot", "value": "temp_chart.png" }
```

Q: What was the value of shares traded on 2023-12-12?
Variable `dfs: list[pd.DataFrame]` is already declared.

At the end, declare "result" variable as a dictionary of type and value.



Generate python code and return full updated code:
2023-12-31 10:40:20 [INFO] Executing Step 2: CodeGenerator
2023-12-31 10:40:23 [INFO] HTTP Request: POST https://api.openai.com/v1/chat/completions "HTTP/1.1 200 OK"
2023-12-31 10:40:23 [INFO] Code generated:
            ```
            # TODO: import the required dependencies
import pandas as pd

# Write code here
value_traded = dfs[0].loc['2023-12-12', 'Volume'] * dfs[0].loc['2023-12-12', 'Close']

# Declare result var
result = {
    "type": "number",
    "value": value_traded
}
            ```
            
2023-12-31 10:40:23 [INFO] Executing Step 3: CachePopulation
2023-12-31 10:40:23 [INFO] Executing Step 4: CodeExecution
2023-12-31 10:40:23 [INFO] Saving charts to C:\Users\mram\OneDrive - Intel Corporation\Python\OpenAI\ChatFun\exports\charts\temp_chart.png
2023-12-31 10:40:23 [INFO] 
Code running:
```
value_traded = dfs[0].loc['2023-12-12', 'Volume'] * dfs[0].loc['2023-12-12', 'Close']
result = {'type': 'number', 'value': value_traded}
        ```
2023-12-31 10:40:23 [INFO] Executing Step 5: ResultValidation
2023-12-31 10:40:23 [INFO] Answer: {'type': 'number', 'value': 1385154916.7953491}
2023-12-31 10:40:23 [INFO] Executed in: 3.484987497329712s
2023-12-31 10:40:23 [INFO] Executing Step 6: ResultParsing
2023-12-31 10:40:44 [INFO] Question: What was the value of shares traded on 2023-12-12? Explain the calculation steps.
2023-12-31 10:40:44 [INFO] Running PandasAI with openai LLM...
2023-12-31 10:40:44 [INFO] Prompt ID: 03568d40-d68c-4383-aef3-d5da9d15ca12
2023-12-31 10:40:44 [INFO] Executing Step 0: CacheLookup
2023-12-31 10:40:44 [INFO] Executing Step 1: PromptGeneration
2023-12-31 10:40:44 [INFO] Using prompt: <dataframe>
dfs[0]:21x6
Open,High,Low,Close,Adj Close,Volume
44.650001525878906,45.09000015258789,44.40999984741211,44.70000076293945,44.70000076293945,46263000
43.29999923706055,43.310001373291016,41.689998626708984,42.349998474121094,42.349998474121094,50417600
44.36000061035156,44.36000061035156,42.86000061035156,43.7400016784668,43.7400016784668,43922500
</dataframe>




Update this initial code:
```python
# TODO: import the required dependencies
import pandas as pd

# Write code here

# Declare result var: type (possible values "string", "number", "dataframe", "plot"). Examples: { "type": "string", "value": f"The highest salary is {highest_salary}." } or { "type": "number", "value": 125 } or { "type": "dataframe", "value": pd.DataFrame({...}) } or { "type": "plot", "value": "temp_chart.png" }
```

Q: What was the value of shares traded on 2023-12-12? Explain the calculation steps.
Variable `dfs: list[pd.DataFrame]` is already declared.

At the end, declare "result" variable as a dictionary of type and value.



Generate python code and return full updated code:
2023-12-31 10:40:44 [INFO] Executing Step 2: CodeGenerator
2023-12-31 10:40:54 [INFO] HTTP Request: POST https://api.openai.com/v1/chat/completions "HTTP/1.1 200 OK"
2023-12-31 10:40:54 [INFO] Code generated:
            ```
            # TODO: import the required dependencies
import pandas as pd

# Write code here
df = dfs[0]  # Get the first dataframe from the list
df['Date'] = pd.to_datetime(df['Date'])  # Convert the 'Date' column to datetime format
df.set_index('Date', inplace=True)  # Set the 'Date' column as the index

# Calculate the value of shares traded on 2023-12-12
shares_traded = df.loc['2023-12-12', 'Volume']
closing_price = df.loc['2023-12-12', 'Close']
value_traded = shares_traded * closing_price

# Declare result var
result = {
    "type": "number",
    "value": value_traded
}
            ```
            
2023-12-31 10:40:54 [INFO] Executing Step 3: CachePopulation
2023-12-31 10:40:54 [INFO] Executing Step 4: CodeExecution
2023-12-31 10:40:54 [INFO] Saving charts to C:\Users\mram\OneDrive - Intel Corporation\Python\OpenAI\ChatFun\exports\charts\temp_chart.png
2023-12-31 10:40:54 [INFO] 
Code running:
```
df = dfs[0]
df['Date'] = pd.to_datetime(df['Date'])
df.set_index('Date', inplace=True)
shares_traded = df.loc['2023-12-12', 'Volume']
closing_price = df.loc['2023-12-12', 'Close']
value_traded = shares_traded * closing_price
result = {'type': 'number', 'value': value_traded}
        ```
2023-12-31 10:40:54 [WARNING] Failed to execute code with a correction framework [retry number: 1]
2023-12-31 10:40:54 [ERROR] Failed with error: Traceback (most recent call last):
  File "C:\Users\mram\AppData\Local\Packages\PythonSoftwareFoundation.Python.3.10_qbz5n2kfra8p0\LocalCache\local-packages\Python310\site-packages\pandas\core\indexes\base.py", line 3802, in get_loc
    return self._engine.get_loc(casted_key)
  File "pandas\_libs\index.pyx", line 138, in pandas._libs.index.IndexEngine.get_loc
  File "pandas\_libs\index.pyx", line 165, in pandas._libs.index.IndexEngine.get_loc
  File "pandas\_libs\hashtable_class_helper.pxi", line 5745, in pandas._libs.hashtable.PyObjectHashTable.get_item
  File "pandas\_libs\hashtable_class_helper.pxi", line 5753, in pandas._libs.hashtable.PyObjectHashTable.get_item
KeyError: 'Date'

The above exception was the direct cause of the following exception:

Traceback (most recent call last):
  File "C:\Users\mram\AppData\Local\Packages\PythonSoftwareFoundation.Python.3.10_qbz5n2kfra8p0\LocalCache\local-packages\Python310\site-packages\pandasai\pipelines\smart_datalake_chat\code_execution.py", line 46, in execute
    result = pipeline_context.query_exec_tracker.execute_func(
  File "C:\Users\mram\AppData\Local\Packages\PythonSoftwareFoundation.Python.3.10_qbz5n2kfra8p0\LocalCache\local-packages\Python310\site-packages\pandasai\helpers\query_exec_tracker.py", line 128, in execute_func
    result = function(*args, **kwargs)
  File "C:\Users\mram\AppData\Local\Packages\PythonSoftwareFoundation.Python.3.10_qbz5n2kfra8p0\LocalCache\local-packages\Python310\site-packages\pandasai\helpers\code_manager.py", line 207, in execute_code
    exec(code_to_run, environment)
  File "<string>", line 2, in <module>
  File "C:\Users\mram\AppData\Local\Packages\PythonSoftwareFoundation.Python.3.10_qbz5n2kfra8p0\LocalCache\local-packages\Python310\site-packages\pandas\core\frame.py", line 3807, in __getitem__
    indexer = self.columns.get_loc(key)
  File "C:\Users\mram\AppData\Local\Packages\PythonSoftwareFoundation.Python.3.10_qbz5n2kfra8p0\LocalCache\local-packages\Python310\site-packages\pandas\core\indexes\base.py", line 3804, in get_loc
    raise KeyError(key) from err
KeyError: 'Date'
. Retrying
2023-12-31 10:40:54 [INFO] Using prompt: <dataframe>
dfs[0]:21x6
Open,High,Low,Close,Adj Close,Volume
44.650001525878906,45.09000015258789,44.40999984741211,44.70000076293945,44.70000076293945,46263000
43.29999923706055,43.310001373291016,41.689998626708984,42.349998474121094,42.349998474121094,50417600
44.36000061035156,44.36000061035156,42.86000061035156,43.7400016784668,43.7400016784668,43922500
</dataframe>

The user asked the following question:
Q: What was the value of shares traded on 2023-12-12? Explain the calculation steps.

You generated this python code:
# TODO: import the required dependencies
import pandas as pd

# Write code here
df = dfs[0]  # Get the first dataframe from the list
df['Date'] = pd.to_datetime(df['Date'])  # Convert the 'Date' column to datetime format
df.set_index('Date', inplace=True)  # Set the 'Date' column as the index

# Calculate the value of shares traded on 2023-12-12
shares_traded = df.loc['2023-12-12', 'Volume']
closing_price = df.loc['2023-12-12', 'Close']
value_traded = shares_traded * closing_price

# Declare result var
result = {
    "type": "number",
    "value": value_traded
}

It fails with the following error:
Traceback (most recent call last):
  File "C:\Users\mram\AppData\Local\Packages\PythonSoftwareFoundation.Python.3.10_qbz5n2kfra8p0\LocalCache\local-packages\Python310\site-packages\pandas\core\indexes\base.py", line 3802, in get_loc
    return self._engine.get_loc(casted_key)
  File "pandas\_libs\index.pyx", line 138, in pandas._libs.index.IndexEngine.get_loc
  File "pandas\_libs\index.pyx", line 165, in pandas._libs.index.IndexEngine.get_loc
  File "pandas\_libs\hashtable_class_helper.pxi", line 5745, in pandas._libs.hashtable.PyObjectHashTable.get_item
  File "pandas\_libs\hashtable_class_helper.pxi", line 5753, in pandas._libs.hashtable.PyObjectHashTable.get_item
KeyError: 'Date'

The above exception was the direct cause of the following exception:

Traceback (most recent call last):
  File "C:\Users\mram\AppData\Local\Packages\PythonSoftwareFoundation.Python.3.10_qbz5n2kfra8p0\LocalCache\local-packages\Python310\site-packages\pandasai\pipelines\smart_datalake_chat\code_execution.py", line 46, in execute
    result = pipeline_context.query_exec_tracker.execute_func(
  File "C:\Users\mram\AppData\Local\Packages\PythonSoftwareFoundation.Python.3.10_qbz5n2kfra8p0\LocalCache\local-packages\Python310\site-packages\pandasai\helpers\query_exec_tracker.py", line 128, in execute_func
    result = function(*args, **kwargs)
  File "C:\Users\mram\AppData\Local\Packages\PythonSoftwareFoundation.Python.3.10_qbz5n2kfra8p0\LocalCache\local-packages\Python310\site-packages\pandasai\helpers\code_manager.py", line 207, in execute_code
    exec(code_to_run, environment)
  File "<string>", line 2, in <module>
  File "C:\Users\mram\AppData\Local\Packages\PythonSoftwareFoundation.Python.3.10_qbz5n2kfra8p0\LocalCache\local-packages\Python310\site-packages\pandas\core\frame.py", line 3807, in __getitem__
    indexer = self.columns.get_loc(key)
  File "C:\Users\mram\AppData\Local\Packages\PythonSoftwareFoundation.Python.3.10_qbz5n2kfra8p0\LocalCache\local-packages\Python310\site-packages\pandas\core\indexes\base.py", line 3804, in get_loc
    raise KeyError(key) from err
KeyError: 'Date'


Fix the python code above and return the new python code:
2023-12-31 10:41:00 [INFO] HTTP Request: POST https://api.openai.com/v1/chat/completions "HTTP/1.1 200 OK"
2023-12-31 10:41:00 [INFO] Saving charts to C:\Users\mram\OneDrive - Intel Corporation\Python\OpenAI\ChatFun\exports\charts\temp_chart.png
2023-12-31 10:41:00 [INFO] 
Code running:
```
df = dfs[0]
df['Date'] = pd.to_datetime(df.index)
df.set_index('Date', inplace=True)
shares_traded = df.loc['2023-12-12', 'Volume']
closing_price = df.loc['2023-12-12', 'Close']
value_traded = shares_traded * closing_price
result = {'type': 'number', 'value': value_traded}
result
        ```
2023-12-31 10:41:00 [INFO] Executing Step 5: ResultValidation
2023-12-31 10:41:00 [INFO] Answer: {'type': 'number', 'value': 1385154916.7953491}
2023-12-31 10:41:00 [INFO] Executed in: 15.658395051956177s
2023-12-31 10:41:00 [INFO] Executing Step 6: ResultParsing
2023-12-31 10:53:52 [INFO] Question: What was the price on 2023-12-12?
2023-12-31 10:53:52 [INFO] Running PandasAI with openai LLM...
2023-12-31 10:53:52 [INFO] Prompt ID: cd9b71a5-eae4-4c94-a46d-235b1a0f7459
2023-12-31 10:53:52 [INFO] Executing Step 0: CacheLookup
2023-12-31 10:53:52 [INFO] Using cached response
2023-12-31 10:53:52 [INFO] Executing Step 1: PromptGeneration
2023-12-31 10:53:52 [INFO] Executing Step 2: CodeGenerator
2023-12-31 10:53:52 [INFO] Executing Step 3: CachePopulation
2023-12-31 10:53:52 [INFO] Executing Step 4: CodeExecution
2023-12-31 10:53:52 [INFO] Saving charts to C:\Users\mram\OneDrive - Intel Corporation\Python\OpenAI\ChatFun\exports\charts\temp_chart.png
2023-12-31 10:53:52 [INFO] 
Code running:
```
date = '2023-12-12'
price = dfs[0][dfs[0].index == date]['Close'].values[0]
result = {'type': 'string', 'value': f'The price on {date} was {price}.'}
        ```
2023-12-31 10:53:52 [INFO] Executing Step 5: ResultValidation
2023-12-31 10:53:52 [INFO] Answer: {'type': 'string', 'value': 'The price on 2023-12-12 was 44.040000915527344.'}
2023-12-31 10:53:52 [INFO] Executed in: 0.040197134017944336s
2023-12-31 10:53:52 [INFO] Executing Step 6: ResultParsing
2023-12-31 10:54:01 [INFO] Question: What was the volume on 2023-12-12?
2023-12-31 10:54:01 [INFO] Running PandasAI with openai LLM...
2023-12-31 10:54:01 [INFO] Prompt ID: e7faed67-c2f5-486b-a19e-1aa908fe25d2
2023-12-31 10:54:01 [INFO] Executing Step 0: CacheLookup
2023-12-31 10:54:01 [INFO] Executing Step 1: PromptGeneration
2023-12-31 10:54:01 [INFO] Using prompt: <dataframe>
dfs[0]:21x6
Open,High,Low,Close,Adj Close,Volume
43.29999923706055,43.310001373291016,41.689998626708984,42.349998474121094,42.349998474121094,50417600
44.650001525878906,45.09000015258789,44.40999984741211,44.70000076293945,44.70000076293945,46263000
44.36000061035156,44.36000061035156,42.86000061035156,43.7400016784668,43.7400016784668,43922500
</dataframe>




Update this initial code:
```python
# TODO: import the required dependencies
import pandas as pd

# Write code here

# Declare result var: type (possible values "string", "number", "dataframe", "plot"). Examples: { "type": "string", "value": f"The highest salary is {highest_salary}." } or { "type": "number", "value": 125 } or { "type": "dataframe", "value": pd.DataFrame({...}) } or { "type": "plot", "value": "temp_chart.png" }
```

Q: What was the volume on 2023-12-12?
Variable `dfs: list[pd.DataFrame]` is already declared.

At the end, declare "result" variable as a dictionary of type and value.



Generate python code and return full updated code:
2023-12-31 10:54:01 [INFO] Executing Step 2: CodeGenerator
2023-12-31 10:54:03 [INFO] HTTP Request: POST https://api.openai.com/v1/chat/completions "HTTP/1.1 200 OK"
2023-12-31 10:54:03 [INFO] Code generated:
            ```
            # TODO: import the required dependencies
import pandas as pd

# Write code here
volume = dfs[0].loc['2023-12-12', 'Volume']

# Declare result var
result = {
    "type": "number",
    "value": volume
}
            ```
            
2023-12-31 10:54:03 [INFO] Executing Step 3: CachePopulation
2023-12-31 10:54:03 [INFO] Executing Step 4: CodeExecution
2023-12-31 10:54:03 [INFO] Saving charts to C:\Users\mram\OneDrive - Intel Corporation\Python\OpenAI\ChatFun\exports\charts\temp_chart.png
2023-12-31 10:54:03 [INFO] 
Code running:
```
volume = dfs[0].loc['2023-12-12', 'Volume']
result = {'type': 'number', 'value': volume}
        ```
2023-12-31 10:54:03 [INFO] Executing Step 5: ResultValidation
2023-12-31 10:54:03 [INFO] Answer: {'type': 'number', 'value': 31452200.0}
2023-12-31 10:54:03 [INFO] Executed in: 2.4836432933807373s
2023-12-31 10:54:03 [INFO] Executing Step 6: ResultParsing
2024-01-10 18:32:19 [INFO] Question: What was the price on 2024-01-01
2024-01-10 18:32:19 [INFO] Running PandasAI with openai LLM...
2024-01-10 18:32:19 [INFO] Prompt ID: 69d547fc-7414-4ea5-9855-ef0ffc399898
2024-01-10 18:32:19 [INFO] Executing Step 0: CacheLookup
2024-01-10 18:32:19 [INFO] Executing Step 1: PromptGeneration
2024-01-10 18:32:19 [INFO] Using prompt: <dataframe>
dfs[0]:21x6
Open,High,Low,Close,Adj Close,Volume
44.36000061035156,44.439998626708984,43.630001068115234,44.040000915527344,44.040000915527344,31452200
43.15999984741211,44.72999954223633,43.08000183105469,44.540000915527344,44.540000915527344,48288200
44.08000183105469,44.720001220703125,43.33000183105469,44.56999969482422,44.56999969482422,35216100
</dataframe>




Update this initial code:
```python
# TODO: import the required dependencies
import pandas as pd

# Write code here

# Declare result var: type (possible values "string", "number", "dataframe", "plot"). Examples: { "type": "string", "value": f"The highest salary is {highest_salary}." } or { "type": "number", "value": 125 } or { "type": "dataframe", "value": pd.DataFrame({...}) } or { "type": "plot", "value": "temp_chart.png" }
```

Q: What was the price on 2024-01-01
Variable `dfs: list[pd.DataFrame]` is already declared.

At the end, declare "result" variable as a dictionary of type and value.



Generate python code and return full updated code:
2024-01-10 18:32:19 [INFO] Executing Step 2: CodeGenerator
2024-01-10 18:32:23 [INFO] HTTP Request: POST https://api.openai.com/v1/chat/completions "HTTP/1.1 200 OK"
2024-01-10 18:32:23 [INFO] Code generated:
            ```
            # TODO: import the required dependencies
import pandas as pd

# Write code here
price = dfs[0].loc['2024-01-01', 'Close']

# Declare result var
result = {
    "type": "number",
    "value": price
}
            ```
            
2024-01-10 18:32:23 [INFO] Executing Step 3: CachePopulation
2024-01-10 18:32:23 [INFO] Executing Step 4: CodeExecution
2024-01-10 18:32:23 [INFO] Saving charts to C:\Users\mram\OneDrive - Intel Corporation\Python\OpenAI\ChatFun\exports\charts\temp_chart.png
2024-01-10 18:32:23 [INFO] 
Code running:
```
price = dfs[0].loc['2024-01-01', 'Close']
result = {'type': 'number', 'value': price}
        ```
2024-01-10 18:32:23 [WARNING] Failed to execute code with a correction framework [retry number: 1]
2024-01-10 18:32:23 [ERROR] Failed with error: Traceback (most recent call last):
  File "pandas\_libs\index.pyx", line 548, in pandas._libs.index.DatetimeEngine.get_loc
  File "pandas\_libs\hashtable_class_helper.pxi", line 2263, in pandas._libs.hashtable.Int64HashTable.get_item
  File "pandas\_libs\hashtable_class_helper.pxi", line 2273, in pandas._libs.hashtable.Int64HashTable.get_item
KeyError: 1704067200000000000

During handling of the above exception, another exception occurred:

Traceback (most recent call last):
  File "C:\Users\mram\AppData\Local\Packages\PythonSoftwareFoundation.Python.3.10_qbz5n2kfra8p0\LocalCache\local-packages\Python310\site-packages\pandas\core\indexes\base.py", line 3802, in get_loc
    return self._engine.get_loc(casted_key)
  File "pandas\_libs\index.pyx", line 516, in pandas._libs.index.DatetimeEngine.get_loc
  File "pandas\_libs\index.pyx", line 550, in pandas._libs.index.DatetimeEngine.get_loc
KeyError: Timestamp('2024-01-01 00:00:00')

The above exception was the direct cause of the following exception:

Traceback (most recent call last):
  File "C:\Users\mram\AppData\Local\Packages\PythonSoftwareFoundation.Python.3.10_qbz5n2kfra8p0\LocalCache\local-packages\Python310\site-packages\pandas\core\indexes\datetimes.py", line 736, in get_loc
    return Index.get_loc(self, key, method, tolerance)
  File "C:\Users\mram\AppData\Local\Packages\PythonSoftwareFoundation.Python.3.10_qbz5n2kfra8p0\LocalCache\local-packages\Python310\site-packages\pandas\core\indexes\base.py", line 3804, in get_loc
    raise KeyError(key) from err
KeyError: Timestamp('2024-01-01 00:00:00')

The above exception was the direct cause of the following exception:

Traceback (most recent call last):
  File "C:\Users\mram\AppData\Local\Packages\PythonSoftwareFoundation.Python.3.10_qbz5n2kfra8p0\LocalCache\local-packages\Python310\site-packages\pandasai\pipelines\smart_datalake_chat\code_execution.py", line 46, in execute
    result = pipeline_context.query_exec_tracker.execute_func(
  File "C:\Users\mram\AppData\Local\Packages\PythonSoftwareFoundation.Python.3.10_qbz5n2kfra8p0\LocalCache\local-packages\Python310\site-packages\pandasai\helpers\query_exec_tracker.py", line 128, in execute_func
    result = function(*args, **kwargs)
  File "C:\Users\mram\AppData\Local\Packages\PythonSoftwareFoundation.Python.3.10_qbz5n2kfra8p0\LocalCache\local-packages\Python310\site-packages\pandasai\helpers\code_manager.py", line 207, in execute_code
    exec(code_to_run, environment)
  File "<string>", line 1, in <module>
  File "C:\Users\mram\AppData\Local\Packages\PythonSoftwareFoundation.Python.3.10_qbz5n2kfra8p0\LocalCache\local-packages\Python310\site-packages\pandas\core\indexing.py", line 1067, in __getitem__
    return self._getitem_tuple(key)
  File "C:\Users\mram\AppData\Local\Packages\PythonSoftwareFoundation.Python.3.10_qbz5n2kfra8p0\LocalCache\local-packages\Python310\site-packages\pandas\core\indexing.py", line 1247, in _getitem_tuple
    return self._getitem_lowerdim(tup)
  File "C:\Users\mram\AppData\Local\Packages\PythonSoftwareFoundation.Python.3.10_qbz5n2kfra8p0\LocalCache\local-packages\Python310\site-packages\pandas\core\indexing.py", line 967, in _getitem_lowerdim
    section = self._getitem_axis(key, axis=i)
  File "C:\Users\mram\AppData\Local\Packages\PythonSoftwareFoundation.Python.3.10_qbz5n2kfra8p0\LocalCache\local-packages\Python310\site-packages\pandas\core\indexing.py", line 1312, in _getitem_axis
    return self._get_label(key, axis=axis)
  File "C:\Users\mram\AppData\Local\Packages\PythonSoftwareFoundation.Python.3.10_qbz5n2kfra8p0\LocalCache\local-packages\Python310\site-packages\pandas\core\indexing.py", line 1260, in _get_label
    return self.obj.xs(label, axis=axis)
  File "C:\Users\mram\AppData\Local\Packages\PythonSoftwareFoundation.Python.3.10_qbz5n2kfra8p0\LocalCache\local-packages\Python310\site-packages\pandas\core\generic.py", line 4056, in xs
    loc = index.get_loc(key)
  File "C:\Users\mram\AppData\Local\Packages\PythonSoftwareFoundation.Python.3.10_qbz5n2kfra8p0\LocalCache\local-packages\Python310\site-packages\pandas\core\indexes\datetimes.py", line 738, in get_loc
    raise KeyError(orig_key) from err
KeyError: '2024-01-01'
. Retrying
2024-01-10 18:32:23 [INFO] Using prompt: <dataframe>
dfs[0]:21x6
Open,High,Low,Close,Adj Close,Volume
44.36000061035156,44.439998626708984,43.630001068115234,44.040000915527344,44.040000915527344,31452200
43.15999984741211,44.72999954223633,43.08000183105469,44.540000915527344,44.540000915527344,48288200
44.08000183105469,44.720001220703125,43.33000183105469,44.56999969482422,44.56999969482422,35216100
</dataframe>

The user asked the following question:
Q: What was the price on 2024-01-01

You generated this python code:
# TODO: import the required dependencies
import pandas as pd

# Write code here
price = dfs[0].loc['2024-01-01', 'Close']

# Declare result var
result = {
    "type": "number",
    "value": price
}

It fails with the following error:
Traceback (most recent call last):
  File "pandas\_libs\index.pyx", line 548, in pandas._libs.index.DatetimeEngine.get_loc
  File "pandas\_libs\hashtable_class_helper.pxi", line 2263, in pandas._libs.hashtable.Int64HashTable.get_item
  File "pandas\_libs\hashtable_class_helper.pxi", line 2273, in pandas._libs.hashtable.Int64HashTable.get_item
KeyError: 1704067200000000000

During handling of the above exception, another exception occurred:

Traceback (most recent call last):
  File "C:\Users\mram\AppData\Local\Packages\PythonSoftwareFoundation.Python.3.10_qbz5n2kfra8p0\LocalCache\local-packages\Python310\site-packages\pandas\core\indexes\base.py", line 3802, in get_loc
    return self._engine.get_loc(casted_key)
  File "pandas\_libs\index.pyx", line 516, in pandas._libs.index.DatetimeEngine.get_loc
  File "pandas\_libs\index.pyx", line 550, in pandas._libs.index.DatetimeEngine.get_loc
KeyError: Timestamp('2024-01-01 00:00:00')

The above exception was the direct cause of the following exception:

Traceback (most recent call last):
  File "C:\Users\mram\AppData\Local\Packages\PythonSoftwareFoundation.Python.3.10_qbz5n2kfra8p0\LocalCache\local-packages\Python310\site-packages\pandas\core\indexes\datetimes.py", line 736, in get_loc
    return Index.get_loc(self, key, method, tolerance)
  File "C:\Users\mram\AppData\Local\Packages\PythonSoftwareFoundation.Python.3.10_qbz5n2kfra8p0\LocalCache\local-packages\Python310\site-packages\pandas\core\indexes\base.py", line 3804, in get_loc
    raise KeyError(key) from err
KeyError: Timestamp('2024-01-01 00:00:00')

The above exception was the direct cause of the following exception:

Traceback (most recent call last):
  File "C:\Users\mram\AppData\Local\Packages\PythonSoftwareFoundation.Python.3.10_qbz5n2kfra8p0\LocalCache\local-packages\Python310\site-packages\pandasai\pipelines\smart_datalake_chat\code_execution.py", line 46, in execute
    result = pipeline_context.query_exec_tracker.execute_func(
  File "C:\Users\mram\AppData\Local\Packages\PythonSoftwareFoundation.Python.3.10_qbz5n2kfra8p0\LocalCache\local-packages\Python310\site-packages\pandasai\helpers\query_exec_tracker.py", line 128, in execute_func
    result = function(*args, **kwargs)
  File "C:\Users\mram\AppData\Local\Packages\PythonSoftwareFoundation.Python.3.10_qbz5n2kfra8p0\LocalCache\local-packages\Python310\site-packages\pandasai\helpers\code_manager.py", line 207, in execute_code
    exec(code_to_run, environment)
  File "<string>", line 1, in <module>
  File "C:\Users\mram\AppData\Local\Packages\PythonSoftwareFoundation.Python.3.10_qbz5n2kfra8p0\LocalCache\local-packages\Python310\site-packages\pandas\core\indexing.py", line 1067, in __getitem__
    return self._getitem_tuple(key)
  File "C:\Users\mram\AppData\Local\Packages\PythonSoftwareFoundation.Python.3.10_qbz5n2kfra8p0\LocalCache\local-packages\Python310\site-packages\pandas\core\indexing.py", line 1247, in _getitem_tuple
    return self._getitem_lowerdim(tup)
  File "C:\Users\mram\AppData\Local\Packages\PythonSoftwareFoundation.Python.3.10_qbz5n2kfra8p0\LocalCache\local-packages\Python310\site-packages\pandas\core\indexing.py", line 967, in _getitem_lowerdim
    section = self._getitem_axis(key, axis=i)
  File "C:\Users\mram\AppData\Local\Packages\PythonSoftwareFoundation.Python.3.10_qbz5n2kfra8p0\LocalCache\local-packages\Python310\site-packages\pandas\core\indexing.py", line 1312, in _getitem_axis
    return self._get_label(key, axis=axis)
  File "C:\Users\mram\AppData\Local\Packages\PythonSoftwareFoundation.Python.3.10_qbz5n2kfra8p0\LocalCache\local-packages\Python310\site-packages\pandas\core\indexing.py", line 1260, in _get_label
    return self.obj.xs(label, axis=axis)
  File "C:\Users\mram\AppData\Local\Packages\PythonSoftwareFoundation.Python.3.10_qbz5n2kfra8p0\LocalCache\local-packages\Python310\site-packages\pandas\core\generic.py", line 4056, in xs
    loc = index.get_loc(key)
  File "C:\Users\mram\AppData\Local\Packages\PythonSoftwareFoundation.Python.3.10_qbz5n2kfra8p0\LocalCache\local-packages\Python310\site-packages\pandas\core\indexes\datetimes.py", line 738, in get_loc
    raise KeyError(orig_key) from err
KeyError: '2024-01-01'


Fix the python code above and return the new python code:
2024-01-10 18:32:26 [INFO] HTTP Request: POST https://api.openai.com/v1/chat/completions "HTTP/1.1 200 OK"
2024-01-10 18:32:26 [INFO] Saving charts to C:\Users\mram\OneDrive - Intel Corporation\Python\OpenAI\ChatFun\exports\charts\temp_chart.png
2024-01-10 18:32:26 [INFO] 
Code running:
```
price = dfs[0].loc['2024-01-01', 'Close']
result = {'type': 'number', 'value': price}
result
        ```
2024-01-10 18:32:26 [WARNING] Failed to execute code with a correction framework [retry number: 2]
2024-01-10 18:32:26 [ERROR] Failed with error: Traceback (most recent call last):
  File "pandas\_libs\index.pyx", line 548, in pandas._libs.index.DatetimeEngine.get_loc
  File "pandas\_libs\hashtable_class_helper.pxi", line 2263, in pandas._libs.hashtable.Int64HashTable.get_item
  File "pandas\_libs\hashtable_class_helper.pxi", line 2273, in pandas._libs.hashtable.Int64HashTable.get_item
KeyError: 1704067200000000000

During handling of the above exception, another exception occurred:

Traceback (most recent call last):
  File "C:\Users\mram\AppData\Local\Packages\PythonSoftwareFoundation.Python.3.10_qbz5n2kfra8p0\LocalCache\local-packages\Python310\site-packages\pandas\core\indexes\base.py", line 3802, in get_loc
    return self._engine.get_loc(casted_key)
  File "pandas\_libs\index.pyx", line 516, in pandas._libs.index.DatetimeEngine.get_loc
  File "pandas\_libs\index.pyx", line 550, in pandas._libs.index.DatetimeEngine.get_loc
KeyError: Timestamp('2024-01-01 00:00:00')

The above exception was the direct cause of the following exception:

Traceback (most recent call last):
  File "C:\Users\mram\AppData\Local\Packages\PythonSoftwareFoundation.Python.3.10_qbz5n2kfra8p0\LocalCache\local-packages\Python310\site-packages\pandas\core\indexes\datetimes.py", line 736, in get_loc
    return Index.get_loc(self, key, method, tolerance)
  File "C:\Users\mram\AppData\Local\Packages\PythonSoftwareFoundation.Python.3.10_qbz5n2kfra8p0\LocalCache\local-packages\Python310\site-packages\pandas\core\indexes\base.py", line 3804, in get_loc
    raise KeyError(key) from err
KeyError: Timestamp('2024-01-01 00:00:00')

The above exception was the direct cause of the following exception:

Traceback (most recent call last):
  File "C:\Users\mram\AppData\Local\Packages\PythonSoftwareFoundation.Python.3.10_qbz5n2kfra8p0\LocalCache\local-packages\Python310\site-packages\pandasai\pipelines\smart_datalake_chat\code_execution.py", line 46, in execute
    result = pipeline_context.query_exec_tracker.execute_func(
  File "C:\Users\mram\AppData\Local\Packages\PythonSoftwareFoundation.Python.3.10_qbz5n2kfra8p0\LocalCache\local-packages\Python310\site-packages\pandasai\helpers\query_exec_tracker.py", line 128, in execute_func
    result = function(*args, **kwargs)
  File "C:\Users\mram\AppData\Local\Packages\PythonSoftwareFoundation.Python.3.10_qbz5n2kfra8p0\LocalCache\local-packages\Python310\site-packages\pandasai\helpers\code_manager.py", line 207, in execute_code
    exec(code_to_run, environment)
  File "<string>", line 1, in <module>
  File "C:\Users\mram\AppData\Local\Packages\PythonSoftwareFoundation.Python.3.10_qbz5n2kfra8p0\LocalCache\local-packages\Python310\site-packages\pandas\core\indexing.py", line 1067, in __getitem__
    return self._getitem_tuple(key)
  File "C:\Users\mram\AppData\Local\Packages\PythonSoftwareFoundation.Python.3.10_qbz5n2kfra8p0\LocalCache\local-packages\Python310\site-packages\pandas\core\indexing.py", line 1247, in _getitem_tuple
    return self._getitem_lowerdim(tup)
  File "C:\Users\mram\AppData\Local\Packages\PythonSoftwareFoundation.Python.3.10_qbz5n2kfra8p0\LocalCache\local-packages\Python310\site-packages\pandas\core\indexing.py", line 967, in _getitem_lowerdim
    section = self._getitem_axis(key, axis=i)
  File "C:\Users\mram\AppData\Local\Packages\PythonSoftwareFoundation.Python.3.10_qbz5n2kfra8p0\LocalCache\local-packages\Python310\site-packages\pandas\core\indexing.py", line 1312, in _getitem_axis
    return self._get_label(key, axis=axis)
  File "C:\Users\mram\AppData\Local\Packages\PythonSoftwareFoundation.Python.3.10_qbz5n2kfra8p0\LocalCache\local-packages\Python310\site-packages\pandas\core\indexing.py", line 1260, in _get_label
    return self.obj.xs(label, axis=axis)
  File "C:\Users\mram\AppData\Local\Packages\PythonSoftwareFoundation.Python.3.10_qbz5n2kfra8p0\LocalCache\local-packages\Python310\site-packages\pandas\core\generic.py", line 4056, in xs
    loc = index.get_loc(key)
  File "C:\Users\mram\AppData\Local\Packages\PythonSoftwareFoundation.Python.3.10_qbz5n2kfra8p0\LocalCache\local-packages\Python310\site-packages\pandas\core\indexes\datetimes.py", line 738, in get_loc
    raise KeyError(orig_key) from err
KeyError: '2024-01-01'
. Retrying
2024-01-10 18:32:26 [INFO] Using prompt: <dataframe>
dfs[0]:21x6
Open,High,Low,Close,Adj Close,Volume
44.36000061035156,44.439998626708984,43.630001068115234,44.040000915527344,44.040000915527344,31452200
43.15999984741211,44.72999954223633,43.08000183105469,44.540000915527344,44.540000915527344,48288200
44.08000183105469,44.720001220703125,43.33000183105469,44.56999969482422,44.56999969482422,35216100
</dataframe>

The user asked the following question:
Q: What was the price on 2024-01-01

You generated this python code:
# TODO: import the required dependencies
import pandas as pd

# Write code here
price = dfs[0].loc['2024-01-01', 'Close']

# Declare result var
result = {
    "type": "number",
    "value": price
}

It fails with the following error:
Traceback (most recent call last):
  File "pandas\_libs\index.pyx", line 548, in pandas._libs.index.DatetimeEngine.get_loc
  File "pandas\_libs\hashtable_class_helper.pxi", line 2263, in pandas._libs.hashtable.Int64HashTable.get_item
  File "pandas\_libs\hashtable_class_helper.pxi", line 2273, in pandas._libs.hashtable.Int64HashTable.get_item
KeyError: 1704067200000000000

During handling of the above exception, another exception occurred:

Traceback (most recent call last):
  File "C:\Users\mram\AppData\Local\Packages\PythonSoftwareFoundation.Python.3.10_qbz5n2kfra8p0\LocalCache\local-packages\Python310\site-packages\pandas\core\indexes\base.py", line 3802, in get_loc
    return self._engine.get_loc(casted_key)
  File "pandas\_libs\index.pyx", line 516, in pandas._libs.index.DatetimeEngine.get_loc
  File "pandas\_libs\index.pyx", line 550, in pandas._libs.index.DatetimeEngine.get_loc
KeyError: Timestamp('2024-01-01 00:00:00')

The above exception was the direct cause of the following exception:

Traceback (most recent call last):
  File "C:\Users\mram\AppData\Local\Packages\PythonSoftwareFoundation.Python.3.10_qbz5n2kfra8p0\LocalCache\local-packages\Python310\site-packages\pandas\core\indexes\datetimes.py", line 736, in get_loc
    return Index.get_loc(self, key, method, tolerance)
  File "C:\Users\mram\AppData\Local\Packages\PythonSoftwareFoundation.Python.3.10_qbz5n2kfra8p0\LocalCache\local-packages\Python310\site-packages\pandas\core\indexes\base.py", line 3804, in get_loc
    raise KeyError(key) from err
KeyError: Timestamp('2024-01-01 00:00:00')

The above exception was the direct cause of the following exception:

Traceback (most recent call last):
  File "C:\Users\mram\AppData\Local\Packages\PythonSoftwareFoundation.Python.3.10_qbz5n2kfra8p0\LocalCache\local-packages\Python310\site-packages\pandasai\pipelines\smart_datalake_chat\code_execution.py", line 46, in execute
    result = pipeline_context.query_exec_tracker.execute_func(
  File "C:\Users\mram\AppData\Local\Packages\PythonSoftwareFoundation.Python.3.10_qbz5n2kfra8p0\LocalCache\local-packages\Python310\site-packages\pandasai\helpers\query_exec_tracker.py", line 128, in execute_func
    result = function(*args, **kwargs)
  File "C:\Users\mram\AppData\Local\Packages\PythonSoftwareFoundation.Python.3.10_qbz5n2kfra8p0\LocalCache\local-packages\Python310\site-packages\pandasai\helpers\code_manager.py", line 207, in execute_code
    exec(code_to_run, environment)
  File "<string>", line 1, in <module>
  File "C:\Users\mram\AppData\Local\Packages\PythonSoftwareFoundation.Python.3.10_qbz5n2kfra8p0\LocalCache\local-packages\Python310\site-packages\pandas\core\indexing.py", line 1067, in __getitem__
    return self._getitem_tuple(key)
  File "C:\Users\mram\AppData\Local\Packages\PythonSoftwareFoundation.Python.3.10_qbz5n2kfra8p0\LocalCache\local-packages\Python310\site-packages\pandas\core\indexing.py", line 1247, in _getitem_tuple
    return self._getitem_lowerdim(tup)
  File "C:\Users\mram\AppData\Local\Packages\PythonSoftwareFoundation.Python.3.10_qbz5n2kfra8p0\LocalCache\local-packages\Python310\site-packages\pandas\core\indexing.py", line 967, in _getitem_lowerdim
    section = self._getitem_axis(key, axis=i)
  File "C:\Users\mram\AppData\Local\Packages\PythonSoftwareFoundation.Python.3.10_qbz5n2kfra8p0\LocalCache\local-packages\Python310\site-packages\pandas\core\indexing.py", line 1312, in _getitem_axis
    return self._get_label(key, axis=axis)
  File "C:\Users\mram\AppData\Local\Packages\PythonSoftwareFoundation.Python.3.10_qbz5n2kfra8p0\LocalCache\local-packages\Python310\site-packages\pandas\core\indexing.py", line 1260, in _get_label
    return self.obj.xs(label, axis=axis)
  File "C:\Users\mram\AppData\Local\Packages\PythonSoftwareFoundation.Python.3.10_qbz5n2kfra8p0\LocalCache\local-packages\Python310\site-packages\pandas\core\generic.py", line 4056, in xs
    loc = index.get_loc(key)
  File "C:\Users\mram\AppData\Local\Packages\PythonSoftwareFoundation.Python.3.10_qbz5n2kfra8p0\LocalCache\local-packages\Python310\site-packages\pandas\core\indexes\datetimes.py", line 738, in get_loc
    raise KeyError(orig_key) from err
KeyError: '2024-01-01'


Fix the python code above and return the new python code:
2024-01-10 18:32:29 [INFO] HTTP Request: POST https://api.openai.com/v1/chat/completions "HTTP/1.1 200 OK"
2024-01-10 18:32:29 [INFO] Saving charts to C:\Users\mram\OneDrive - Intel Corporation\Python\OpenAI\ChatFun\exports\charts\temp_chart.png
2024-01-10 18:32:29 [INFO] 
Code running:
```
price = dfs[0].loc['2024-01-01', 'Close']
result = {'type': 'number', 'value': price}
result
        ```
2024-01-10 18:32:29 [ERROR] Pipeline failed on step 4: '2024-01-01'
2024-01-10 18:32:51 [INFO] Question: What was the price on 2024-01-02
2024-01-10 18:32:51 [INFO] Running PandasAI with openai LLM...
2024-01-10 18:32:51 [INFO] Prompt ID: 365b87d7-d381-4f88-b15f-eab49f22667c
2024-01-10 18:32:51 [INFO] Executing Step 0: CacheLookup
2024-01-10 18:32:51 [INFO] Executing Step 1: PromptGeneration
2024-01-10 18:32:51 [INFO] Using prompt: <dataframe>
dfs[0]:21x6
Open,High,Low,Close,Adj Close,Volume
44.08000183105469,44.720001220703125,43.33000183105469,44.56999969482422,44.56999969482422,35216100
44.36000061035156,44.439998626708984,43.630001068115234,44.040000915527344,44.040000915527344,31452200
43.15999984741211,44.72999954223633,43.08000183105469,44.540000915527344,44.540000915527344,48288200
</dataframe>




Update this initial code:
```python
# TODO: import the required dependencies
import pandas as pd

# Write code here

# Declare result var: type (possible values "string", "number", "dataframe", "plot"). Examples: { "type": "string", "value": f"The highest salary is {highest_salary}." } or { "type": "number", "value": 125 } or { "type": "dataframe", "value": pd.DataFrame({...}) } or { "type": "plot", "value": "temp_chart.png" }
```

Q: What was the price on 2024-01-02
Variable `dfs: list[pd.DataFrame]` is already declared.

At the end, declare "result" variable as a dictionary of type and value.



Generate python code and return full updated code:
2024-01-10 18:32:51 [INFO] Executing Step 2: CodeGenerator
2024-01-10 18:32:56 [INFO] HTTP Request: POST https://api.openai.com/v1/chat/completions "HTTP/1.1 200 OK"
2024-01-10 18:32:56 [INFO] Code generated:
            ```
            # TODO: import the required dependencies
import pandas as pd

# Write code here
price = dfs[0].loc['2024-01-02', 'Close']

# Declare result var
result = {
    "type": "number",
    "value": price
}
            ```
            
2024-01-10 18:32:56 [INFO] Executing Step 3: CachePopulation
2024-01-10 18:32:56 [INFO] Executing Step 4: CodeExecution
2024-01-10 18:32:56 [INFO] Saving charts to C:\Users\mram\OneDrive - Intel Corporation\Python\OpenAI\ChatFun\exports\charts\temp_chart.png
2024-01-10 18:32:56 [INFO] 
Code running:
```
price = dfs[0].loc['2024-01-02', 'Close']
result = {'type': 'number', 'value': price}
        ```
2024-01-10 18:32:56 [INFO] Executing Step 5: ResultValidation
2024-01-10 18:32:56 [INFO] Answer: {'type': 'number', 'value': 47.79999923706055}
2024-01-10 18:32:56 [INFO] Executed in: 5.389315128326416s
2024-01-10 18:32:56 [INFO] Executing Step 6: ResultParsing
2024-01-11 00:45:51 [ERROR] 
1 Failed download:
2024-01-11 00:45:51 [ERROR] ['IBM']: Exception('%ticker%: No price data found, symbol may be delisted (period=1mo)')
2024-01-11 06:00:12 [ERROR] 
1 Failed download:
2024-01-11 06:00:12 [ERROR] ['IBM']: Exception('%ticker%: No price data found, symbol may be delisted (period=1mo)')
2024-01-11 10:46:13 [ERROR] 
1 Failed download:
2024-01-11 10:46:13 [ERROR] ['INTC']: Exception('%ticker%: No price data found, symbol may be delisted (period=1mo)')
2024-01-11 10:46:45 [ERROR] 
1 Failed download:
2024-01-11 10:46:45 [ERROR] ['INTC']: Exception('%ticker%: No price data found, symbol may be delisted (period=1mo)')
2024-01-11 10:47:15 [ERROR] 
1 Failed download:
2024-01-11 10:47:15 [ERROR] ['INTC']: Exception('%ticker%: No price data found, symbol may be delisted (period=1mo)')
2024-01-11 10:49:28 [ERROR] 
1 Failed download:
2024-01-11 10:49:28 [ERROR] ['INTC']: Exception('%ticker%: No price data found, symbol may be delisted (period=1mo)')
2024-01-11 10:49:28 [INFO] Question: What was the price on 2023-12-12?
2024-01-11 10:49:28 [INFO] Running PandasAI with openai LLM...
2024-01-11 10:49:28 [INFO] Prompt ID: 2919901f-d031-4048-8f4c-d76eaa7bbd7f
2024-01-11 10:49:28 [INFO] Executing Step 0: CacheLookup
2024-01-11 10:49:28 [INFO] Executing Step 1: PromptGeneration
2024-01-11 10:49:28 [INFO] Using prompt: <dataframe>
dfs[0]:0x6
Open,High,Low,Close,Adj Close,Volume
</dataframe>




Update this initial code:
```python
# TODO: import the required dependencies
import pandas as pd

# Write code here

# Declare result var: type (possible values "string", "number", "dataframe", "plot"). Examples: { "type": "string", "value": f"The highest salary is {highest_salary}." } or { "type": "number", "value": 125 } or { "type": "dataframe", "value": pd.DataFrame({...}) } or { "type": "plot", "value": "temp_chart.png" }
```

Q: What was the price on 2023-12-12?
Variable `dfs: list[pd.DataFrame]` is already declared.

At the end, declare "result" variable as a dictionary of type and value.



Generate python code and return full updated code:
2024-01-11 10:49:28 [INFO] Executing Step 2: CodeGenerator
2024-01-11 10:50:10 [INFO] Retrying request to /chat/completions in 0.822221 seconds
2024-01-12 14:21:17 [INFO] Question: What was the price on 2023-12-12?
2024-01-12 14:21:17 [INFO] Running PandasAI with openai LLM...
2024-01-12 14:21:17 [INFO] Prompt ID: a6c4c0f3-0a8d-4a1a-95a8-7ec2f217421b
2024-01-12 14:21:18 [INFO] Executing Step 0: CacheLookup
2024-01-12 14:21:18 [INFO] Executing Step 1: PromptGeneration
2024-01-12 14:21:18 [INFO] Using prompt: <dataframe>
dfs[0]:21x6
Open,High,Low,Close,Adj Close,Volume
44.08000183105469,44.720001220703125,43.33000183105469,44.56999969482422,44.56999969482422,35216100
45.939998626708984,47.27000045776367,45.66999816894531,46.15999984741211,46.15999984741211,84553800
45.0099983215332,47.06999969482422,44.650001525878906,45.18000030517578,45.18000030517578,70620800
</dataframe>




Update this initial code:
```python
# TODO: import the required dependencies
import pandas as pd

# Write code here

# Declare result var: type (possible values "string", "number", "dataframe", "plot"). Examples: { "type": "string", "value": f"The highest salary is {highest_salary}." } or { "type": "number", "value": 125 } or { "type": "dataframe", "value": pd.DataFrame({...}) } or { "type": "plot", "value": "temp_chart.png" }
```

Q: What was the price on 2023-12-12?
Variable `dfs: list[pd.DataFrame]` is already declared.

At the end, declare "result" variable as a dictionary of type and value.



Generate python code and return full updated code:
2024-01-12 14:21:18 [INFO] Executing Step 2: CodeGenerator
2024-01-12 14:21:20 [INFO] HTTP Request: POST https://api.openai.com/v1/chat/completions "HTTP/1.1 200 OK"
2024-01-12 14:21:20 [INFO] Code generated:
            ```
            # TODO: import the required dependencies
import pandas as pd

# Write code here
price = dfs[0].loc['2023-12-12', 'Close']

# Declare result var
result = {
    "type": "number",
    "value": price
}
            ```
            
2024-01-12 14:21:20 [INFO] Executing Step 3: CachePopulation
2024-01-12 14:21:20 [INFO] Executing Step 4: CodeExecution
2024-01-12 14:21:20 [INFO] Saving charts to C:\Users\mram\OneDrive - Intel Corporation\Python\OpenAI\ChatFun\exports\charts\temp_chart.png
2024-01-12 14:21:20 [INFO] 
Code running:
```
price = dfs[0].loc['2023-12-12', 'Close']
result = {'type': 'number', 'value': price}
        ```
2024-01-12 14:21:20 [WARNING] Failed to execute code with a correction framework [retry number: 1]
2024-01-12 14:21:20 [ERROR] Failed with error: Traceback (most recent call last):
  File "pandas\_libs\index.pyx", line 548, in pandas._libs.index.DatetimeEngine.get_loc
  File "pandas\_libs\hashtable_class_helper.pxi", line 2263, in pandas._libs.hashtable.Int64HashTable.get_item
  File "pandas\_libs\hashtable_class_helper.pxi", line 2273, in pandas._libs.hashtable.Int64HashTable.get_item
KeyError: 1702339200000000000

During handling of the above exception, another exception occurred:

Traceback (most recent call last):
  File "C:\Users\mram\AppData\Local\Packages\PythonSoftwareFoundation.Python.3.10_qbz5n2kfra8p0\LocalCache\local-packages\Python310\site-packages\pandas\core\indexes\base.py", line 3802, in get_loc
    return self._engine.get_loc(casted_key)
  File "pandas\_libs\index.pyx", line 516, in pandas._libs.index.DatetimeEngine.get_loc
  File "pandas\_libs\index.pyx", line 550, in pandas._libs.index.DatetimeEngine.get_loc
KeyError: Timestamp('2023-12-12 00:00:00')

The above exception was the direct cause of the following exception:

Traceback (most recent call last):
  File "C:\Users\mram\AppData\Local\Packages\PythonSoftwareFoundation.Python.3.10_qbz5n2kfra8p0\LocalCache\local-packages\Python310\site-packages\pandas\core\indexes\datetimes.py", line 736, in get_loc
    return Index.get_loc(self, key, method, tolerance)
  File "C:\Users\mram\AppData\Local\Packages\PythonSoftwareFoundation.Python.3.10_qbz5n2kfra8p0\LocalCache\local-packages\Python310\site-packages\pandas\core\indexes\base.py", line 3804, in get_loc
    raise KeyError(key) from err
KeyError: Timestamp('2023-12-12 00:00:00')

The above exception was the direct cause of the following exception:

Traceback (most recent call last):
  File "C:\Users\mram\AppData\Local\Packages\PythonSoftwareFoundation.Python.3.10_qbz5n2kfra8p0\LocalCache\local-packages\Python310\site-packages\pandasai\pipelines\smart_datalake_chat\code_execution.py", line 46, in execute
    result = pipeline_context.query_exec_tracker.execute_func(
  File "C:\Users\mram\AppData\Local\Packages\PythonSoftwareFoundation.Python.3.10_qbz5n2kfra8p0\LocalCache\local-packages\Python310\site-packages\pandasai\helpers\query_exec_tracker.py", line 128, in execute_func
    result = function(*args, **kwargs)
  File "C:\Users\mram\AppData\Local\Packages\PythonSoftwareFoundation.Python.3.10_qbz5n2kfra8p0\LocalCache\local-packages\Python310\site-packages\pandasai\helpers\code_manager.py", line 207, in execute_code
    exec(code_to_run, environment)
  File "<string>", line 1, in <module>
  File "C:\Users\mram\AppData\Local\Packages\PythonSoftwareFoundation.Python.3.10_qbz5n2kfra8p0\LocalCache\local-packages\Python310\site-packages\pandas\core\indexing.py", line 1067, in __getitem__
    return self._getitem_tuple(key)
  File "C:\Users\mram\AppData\Local\Packages\PythonSoftwareFoundation.Python.3.10_qbz5n2kfra8p0\LocalCache\local-packages\Python310\site-packages\pandas\core\indexing.py", line 1247, in _getitem_tuple
    return self._getitem_lowerdim(tup)
  File "C:\Users\mram\AppData\Local\Packages\PythonSoftwareFoundation.Python.3.10_qbz5n2kfra8p0\LocalCache\local-packages\Python310\site-packages\pandas\core\indexing.py", line 967, in _getitem_lowerdim
    section = self._getitem_axis(key, axis=i)
  File "C:\Users\mram\AppData\Local\Packages\PythonSoftwareFoundation.Python.3.10_qbz5n2kfra8p0\LocalCache\local-packages\Python310\site-packages\pandas\core\indexing.py", line 1312, in _getitem_axis
    return self._get_label(key, axis=axis)
  File "C:\Users\mram\AppData\Local\Packages\PythonSoftwareFoundation.Python.3.10_qbz5n2kfra8p0\LocalCache\local-packages\Python310\site-packages\pandas\core\indexing.py", line 1260, in _get_label
    return self.obj.xs(label, axis=axis)
  File "C:\Users\mram\AppData\Local\Packages\PythonSoftwareFoundation.Python.3.10_qbz5n2kfra8p0\LocalCache\local-packages\Python310\site-packages\pandas\core\generic.py", line 4056, in xs
    loc = index.get_loc(key)
  File "C:\Users\mram\AppData\Local\Packages\PythonSoftwareFoundation.Python.3.10_qbz5n2kfra8p0\LocalCache\local-packages\Python310\site-packages\pandas\core\indexes\datetimes.py", line 738, in get_loc
    raise KeyError(orig_key) from err
KeyError: '2023-12-12'
. Retrying
2024-01-12 14:21:20 [INFO] Using prompt: <dataframe>
dfs[0]:21x6
Open,High,Low,Close,Adj Close,Volume
44.08000183105469,44.720001220703125,43.33000183105469,44.56999969482422,44.56999969482422,35216100
45.939998626708984,47.27000045776367,45.66999816894531,46.15999984741211,46.15999984741211,84553800
45.0099983215332,47.06999969482422,44.650001525878906,45.18000030517578,45.18000030517578,70620800
</dataframe>

The user asked the following question:
Q: What was the price on 2023-12-12?

You generated this python code:
# TODO: import the required dependencies
import pandas as pd

# Write code here
price = dfs[0].loc['2023-12-12', 'Close']

# Declare result var
result = {
    "type": "number",
    "value": price
}

It fails with the following error:
Traceback (most recent call last):
  File "pandas\_libs\index.pyx", line 548, in pandas._libs.index.DatetimeEngine.get_loc
  File "pandas\_libs\hashtable_class_helper.pxi", line 2263, in pandas._libs.hashtable.Int64HashTable.get_item
  File "pandas\_libs\hashtable_class_helper.pxi", line 2273, in pandas._libs.hashtable.Int64HashTable.get_item
KeyError: 1702339200000000000

During handling of the above exception, another exception occurred:

Traceback (most recent call last):
  File "C:\Users\mram\AppData\Local\Packages\PythonSoftwareFoundation.Python.3.10_qbz5n2kfra8p0\LocalCache\local-packages\Python310\site-packages\pandas\core\indexes\base.py", line 3802, in get_loc
    return self._engine.get_loc(casted_key)
  File "pandas\_libs\index.pyx", line 516, in pandas._libs.index.DatetimeEngine.get_loc
  File "pandas\_libs\index.pyx", line 550, in pandas._libs.index.DatetimeEngine.get_loc
KeyError: Timestamp('2023-12-12 00:00:00')

The above exception was the direct cause of the following exception:

Traceback (most recent call last):
  File "C:\Users\mram\AppData\Local\Packages\PythonSoftwareFoundation.Python.3.10_qbz5n2kfra8p0\LocalCache\local-packages\Python310\site-packages\pandas\core\indexes\datetimes.py", line 736, in get_loc
    return Index.get_loc(self, key, method, tolerance)
  File "C:\Users\mram\AppData\Local\Packages\PythonSoftwareFoundation.Python.3.10_qbz5n2kfra8p0\LocalCache\local-packages\Python310\site-packages\pandas\core\indexes\base.py", line 3804, in get_loc
    raise KeyError(key) from err
KeyError: Timestamp('2023-12-12 00:00:00')

The above exception was the direct cause of the following exception:

Traceback (most recent call last):
  File "C:\Users\mram\AppData\Local\Packages\PythonSoftwareFoundation.Python.3.10_qbz5n2kfra8p0\LocalCache\local-packages\Python310\site-packages\pandasai\pipelines\smart_datalake_chat\code_execution.py", line 46, in execute
    result = pipeline_context.query_exec_tracker.execute_func(
  File "C:\Users\mram\AppData\Local\Packages\PythonSoftwareFoundation.Python.3.10_qbz5n2kfra8p0\LocalCache\local-packages\Python310\site-packages\pandasai\helpers\query_exec_tracker.py", line 128, in execute_func
    result = function(*args, **kwargs)
  File "C:\Users\mram\AppData\Local\Packages\PythonSoftwareFoundation.Python.3.10_qbz5n2kfra8p0\LocalCache\local-packages\Python310\site-packages\pandasai\helpers\code_manager.py", line 207, in execute_code
    exec(code_to_run, environment)
  File "<string>", line 1, in <module>
  File "C:\Users\mram\AppData\Local\Packages\PythonSoftwareFoundation.Python.3.10_qbz5n2kfra8p0\LocalCache\local-packages\Python310\site-packages\pandas\core\indexing.py", line 1067, in __getitem__
    return self._getitem_tuple(key)
  File "C:\Users\mram\AppData\Local\Packages\PythonSoftwareFoundation.Python.3.10_qbz5n2kfra8p0\LocalCache\local-packages\Python310\site-packages\pandas\core\indexing.py", line 1247, in _getitem_tuple
    return self._getitem_lowerdim(tup)
  File "C:\Users\mram\AppData\Local\Packages\PythonSoftwareFoundation.Python.3.10_qbz5n2kfra8p0\LocalCache\local-packages\Python310\site-packages\pandas\core\indexing.py", line 967, in _getitem_lowerdim
    section = self._getitem_axis(key, axis=i)
  File "C:\Users\mram\AppData\Local\Packages\PythonSoftwareFoundation.Python.3.10_qbz5n2kfra8p0\LocalCache\local-packages\Python310\site-packages\pandas\core\indexing.py", line 1312, in _getitem_axis
    return self._get_label(key, axis=axis)
  File "C:\Users\mram\AppData\Local\Packages\PythonSoftwareFoundation.Python.3.10_qbz5n2kfra8p0\LocalCache\local-packages\Python310\site-packages\pandas\core\indexing.py", line 1260, in _get_label
    return self.obj.xs(label, axis=axis)
  File "C:\Users\mram\AppData\Local\Packages\PythonSoftwareFoundation.Python.3.10_qbz5n2kfra8p0\LocalCache\local-packages\Python310\site-packages\pandas\core\generic.py", line 4056, in xs
    loc = index.get_loc(key)
  File "C:\Users\mram\AppData\Local\Packages\PythonSoftwareFoundation.Python.3.10_qbz5n2kfra8p0\LocalCache\local-packages\Python310\site-packages\pandas\core\indexes\datetimes.py", line 738, in get_loc
    raise KeyError(orig_key) from err
KeyError: '2023-12-12'


Fix the python code above and return the new python code:
2024-01-12 14:21:22 [INFO] HTTP Request: POST https://api.openai.com/v1/chat/completions "HTTP/1.1 200 OK"
2024-01-12 14:21:22 [INFO] Saving charts to C:\Users\mram\OneDrive - Intel Corporation\Python\OpenAI\ChatFun\exports\charts\temp_chart.png
2024-01-12 14:21:22 [INFO] 
Code running:
```
price = dfs[0].loc['2023-12-12', 'Close']
result = {'type': 'number', 'value': price}
result
        ```
2024-01-12 14:21:22 [WARNING] Failed to execute code with a correction framework [retry number: 2]
2024-01-12 14:21:22 [ERROR] Failed with error: Traceback (most recent call last):
  File "pandas\_libs\index.pyx", line 548, in pandas._libs.index.DatetimeEngine.get_loc
  File "pandas\_libs\hashtable_class_helper.pxi", line 2263, in pandas._libs.hashtable.Int64HashTable.get_item
  File "pandas\_libs\hashtable_class_helper.pxi", line 2273, in pandas._libs.hashtable.Int64HashTable.get_item
KeyError: 1702339200000000000

During handling of the above exception, another exception occurred:

Traceback (most recent call last):
  File "C:\Users\mram\AppData\Local\Packages\PythonSoftwareFoundation.Python.3.10_qbz5n2kfra8p0\LocalCache\local-packages\Python310\site-packages\pandas\core\indexes\base.py", line 3802, in get_loc
    return self._engine.get_loc(casted_key)
  File "pandas\_libs\index.pyx", line 516, in pandas._libs.index.DatetimeEngine.get_loc
  File "pandas\_libs\index.pyx", line 550, in pandas._libs.index.DatetimeEngine.get_loc
KeyError: Timestamp('2023-12-12 00:00:00')

The above exception was the direct cause of the following exception:

Traceback (most recent call last):
  File "C:\Users\mram\AppData\Local\Packages\PythonSoftwareFoundation.Python.3.10_qbz5n2kfra8p0\LocalCache\local-packages\Python310\site-packages\pandas\core\indexes\datetimes.py", line 736, in get_loc
    return Index.get_loc(self, key, method, tolerance)
  File "C:\Users\mram\AppData\Local\Packages\PythonSoftwareFoundation.Python.3.10_qbz5n2kfra8p0\LocalCache\local-packages\Python310\site-packages\pandas\core\indexes\base.py", line 3804, in get_loc
    raise KeyError(key) from err
KeyError: Timestamp('2023-12-12 00:00:00')

The above exception was the direct cause of the following exception:

Traceback (most recent call last):
  File "C:\Users\mram\AppData\Local\Packages\PythonSoftwareFoundation.Python.3.10_qbz5n2kfra8p0\LocalCache\local-packages\Python310\site-packages\pandasai\pipelines\smart_datalake_chat\code_execution.py", line 46, in execute
    result = pipeline_context.query_exec_tracker.execute_func(
  File "C:\Users\mram\AppData\Local\Packages\PythonSoftwareFoundation.Python.3.10_qbz5n2kfra8p0\LocalCache\local-packages\Python310\site-packages\pandasai\helpers\query_exec_tracker.py", line 128, in execute_func
    result = function(*args, **kwargs)
  File "C:\Users\mram\AppData\Local\Packages\PythonSoftwareFoundation.Python.3.10_qbz5n2kfra8p0\LocalCache\local-packages\Python310\site-packages\pandasai\helpers\code_manager.py", line 207, in execute_code
    exec(code_to_run, environment)
  File "<string>", line 1, in <module>
  File "C:\Users\mram\AppData\Local\Packages\PythonSoftwareFoundation.Python.3.10_qbz5n2kfra8p0\LocalCache\local-packages\Python310\site-packages\pandas\core\indexing.py", line 1067, in __getitem__
    return self._getitem_tuple(key)
  File "C:\Users\mram\AppData\Local\Packages\PythonSoftwareFoundation.Python.3.10_qbz5n2kfra8p0\LocalCache\local-packages\Python310\site-packages\pandas\core\indexing.py", line 1247, in _getitem_tuple
    return self._getitem_lowerdim(tup)
  File "C:\Users\mram\AppData\Local\Packages\PythonSoftwareFoundation.Python.3.10_qbz5n2kfra8p0\LocalCache\local-packages\Python310\site-packages\pandas\core\indexing.py", line 967, in _getitem_lowerdim
    section = self._getitem_axis(key, axis=i)
  File "C:\Users\mram\AppData\Local\Packages\PythonSoftwareFoundation.Python.3.10_qbz5n2kfra8p0\LocalCache\local-packages\Python310\site-packages\pandas\core\indexing.py", line 1312, in _getitem_axis
    return self._get_label(key, axis=axis)
  File "C:\Users\mram\AppData\Local\Packages\PythonSoftwareFoundation.Python.3.10_qbz5n2kfra8p0\LocalCache\local-packages\Python310\site-packages\pandas\core\indexing.py", line 1260, in _get_label
    return self.obj.xs(label, axis=axis)
  File "C:\Users\mram\AppData\Local\Packages\PythonSoftwareFoundation.Python.3.10_qbz5n2kfra8p0\LocalCache\local-packages\Python310\site-packages\pandas\core\generic.py", line 4056, in xs
    loc = index.get_loc(key)
  File "C:\Users\mram\AppData\Local\Packages\PythonSoftwareFoundation.Python.3.10_qbz5n2kfra8p0\LocalCache\local-packages\Python310\site-packages\pandas\core\indexes\datetimes.py", line 738, in get_loc
    raise KeyError(orig_key) from err
KeyError: '2023-12-12'
. Retrying
2024-01-12 14:21:22 [INFO] Using prompt: <dataframe>
dfs[0]:21x6
Open,High,Low,Close,Adj Close,Volume
44.08000183105469,44.720001220703125,43.33000183105469,44.56999969482422,44.56999969482422,35216100
45.939998626708984,47.27000045776367,45.66999816894531,46.15999984741211,46.15999984741211,84553800
45.0099983215332,47.06999969482422,44.650001525878906,45.18000030517578,45.18000030517578,70620800
</dataframe>

The user asked the following question:
Q: What was the price on 2023-12-12?

You generated this python code:
# TODO: import the required dependencies
import pandas as pd

# Write code here
price = dfs[0].loc['2023-12-12', 'Close']

# Declare result var
result = {
    "type": "number",
    "value": price
}

It fails with the following error:
Traceback (most recent call last):
  File "pandas\_libs\index.pyx", line 548, in pandas._libs.index.DatetimeEngine.get_loc
  File "pandas\_libs\hashtable_class_helper.pxi", line 2263, in pandas._libs.hashtable.Int64HashTable.get_item
  File "pandas\_libs\hashtable_class_helper.pxi", line 2273, in pandas._libs.hashtable.Int64HashTable.get_item
KeyError: 1702339200000000000

During handling of the above exception, another exception occurred:

Traceback (most recent call last):
  File "C:\Users\mram\AppData\Local\Packages\PythonSoftwareFoundation.Python.3.10_qbz5n2kfra8p0\LocalCache\local-packages\Python310\site-packages\pandas\core\indexes\base.py", line 3802, in get_loc
    return self._engine.get_loc(casted_key)
  File "pandas\_libs\index.pyx", line 516, in pandas._libs.index.DatetimeEngine.get_loc
  File "pandas\_libs\index.pyx", line 550, in pandas._libs.index.DatetimeEngine.get_loc
KeyError: Timestamp('2023-12-12 00:00:00')

The above exception was the direct cause of the following exception:

Traceback (most recent call last):
  File "C:\Users\mram\AppData\Local\Packages\PythonSoftwareFoundation.Python.3.10_qbz5n2kfra8p0\LocalCache\local-packages\Python310\site-packages\pandas\core\indexes\datetimes.py", line 736, in get_loc
    return Index.get_loc(self, key, method, tolerance)
  File "C:\Users\mram\AppData\Local\Packages\PythonSoftwareFoundation.Python.3.10_qbz5n2kfra8p0\LocalCache\local-packages\Python310\site-packages\pandas\core\indexes\base.py", line 3804, in get_loc
    raise KeyError(key) from err
KeyError: Timestamp('2023-12-12 00:00:00')

The above exception was the direct cause of the following exception:

Traceback (most recent call last):
  File "C:\Users\mram\AppData\Local\Packages\PythonSoftwareFoundation.Python.3.10_qbz5n2kfra8p0\LocalCache\local-packages\Python310\site-packages\pandasai\pipelines\smart_datalake_chat\code_execution.py", line 46, in execute
    result = pipeline_context.query_exec_tracker.execute_func(
  File "C:\Users\mram\AppData\Local\Packages\PythonSoftwareFoundation.Python.3.10_qbz5n2kfra8p0\LocalCache\local-packages\Python310\site-packages\pandasai\helpers\query_exec_tracker.py", line 128, in execute_func
    result = function(*args, **kwargs)
  File "C:\Users\mram\AppData\Local\Packages\PythonSoftwareFoundation.Python.3.10_qbz5n2kfra8p0\LocalCache\local-packages\Python310\site-packages\pandasai\helpers\code_manager.py", line 207, in execute_code
    exec(code_to_run, environment)
  File "<string>", line 1, in <module>
  File "C:\Users\mram\AppData\Local\Packages\PythonSoftwareFoundation.Python.3.10_qbz5n2kfra8p0\LocalCache\local-packages\Python310\site-packages\pandas\core\indexing.py", line 1067, in __getitem__
    return self._getitem_tuple(key)
  File "C:\Users\mram\AppData\Local\Packages\PythonSoftwareFoundation.Python.3.10_qbz5n2kfra8p0\LocalCache\local-packages\Python310\site-packages\pandas\core\indexing.py", line 1247, in _getitem_tuple
    return self._getitem_lowerdim(tup)
  File "C:\Users\mram\AppData\Local\Packages\PythonSoftwareFoundation.Python.3.10_qbz5n2kfra8p0\LocalCache\local-packages\Python310\site-packages\pandas\core\indexing.py", line 967, in _getitem_lowerdim
    section = self._getitem_axis(key, axis=i)
  File "C:\Users\mram\AppData\Local\Packages\PythonSoftwareFoundation.Python.3.10_qbz5n2kfra8p0\LocalCache\local-packages\Python310\site-packages\pandas\core\indexing.py", line 1312, in _getitem_axis
    return self._get_label(key, axis=axis)
  File "C:\Users\mram\AppData\Local\Packages\PythonSoftwareFoundation.Python.3.10_qbz5n2kfra8p0\LocalCache\local-packages\Python310\site-packages\pandas\core\indexing.py", line 1260, in _get_label
    return self.obj.xs(label, axis=axis)
  File "C:\Users\mram\AppData\Local\Packages\PythonSoftwareFoundation.Python.3.10_qbz5n2kfra8p0\LocalCache\local-packages\Python310\site-packages\pandas\core\generic.py", line 4056, in xs
    loc = index.get_loc(key)
  File "C:\Users\mram\AppData\Local\Packages\PythonSoftwareFoundation.Python.3.10_qbz5n2kfra8p0\LocalCache\local-packages\Python310\site-packages\pandas\core\indexes\datetimes.py", line 738, in get_loc
    raise KeyError(orig_key) from err
KeyError: '2023-12-12'


Fix the python code above and return the new python code:
2024-01-12 14:21:24 [INFO] HTTP Request: POST https://api.openai.com/v1/chat/completions "HTTP/1.1 200 OK"
2024-01-12 14:21:24 [INFO] Saving charts to C:\Users\mram\OneDrive - Intel Corporation\Python\OpenAI\ChatFun\exports\charts\temp_chart.png
2024-01-12 14:21:24 [INFO] 
Code running:
```
price = dfs[0].loc['2023-12-12', 'Close']
result = {'type': 'number', 'value': price}
result
        ```
2024-01-12 14:21:24 [ERROR] Pipeline failed on step 4: '2023-12-12'
2024-01-13 17:52:59 [INFO] Question: What was the price on 2023-12-12?
2024-01-13 17:52:59 [INFO] Running PandasAI with openai LLM...
2024-01-13 17:52:59 [INFO] Prompt ID: abf94b37-6132-41cd-9552-d786d5be2200
2024-01-13 17:52:59 [INFO] Executing Step 0: CacheLookup
2024-01-13 17:52:59 [INFO] Using cached response
2024-01-13 17:52:59 [INFO] Executing Step 1: PromptGeneration
2024-01-13 17:52:59 [INFO] Executing Step 2: CodeGenerator
2024-01-13 17:52:59 [INFO] Executing Step 3: CachePopulation
2024-01-13 17:52:59 [INFO] Executing Step 4: CodeExecution
2024-01-13 17:52:59 [INFO] Saving charts to C:\Users\mram\OneDrive - Intel Corporation\Python\OpenAI\ChatFun\exports\charts\temp_chart.png
2024-01-13 17:52:59 [INFO] 
Code running:
```
price = dfs[0].loc['2023-12-12', 'Close']
result = {'type': 'number', 'value': price}
        ```
2024-01-13 17:52:59 [WARNING] Failed to execute code with a correction framework [retry number: 1]
2024-01-13 17:52:59 [ERROR] Failed with error: Traceback (most recent call last):
  File "pandas\_libs\index.pyx", line 548, in pandas._libs.index.DatetimeEngine.get_loc
  File "pandas\_libs\hashtable_class_helper.pxi", line 2263, in pandas._libs.hashtable.Int64HashTable.get_item
  File "pandas\_libs\hashtable_class_helper.pxi", line 2273, in pandas._libs.hashtable.Int64HashTable.get_item
KeyError: 1702339200000000000

During handling of the above exception, another exception occurred:

Traceback (most recent call last):
  File "C:\Users\mram\AppData\Local\Packages\PythonSoftwareFoundation.Python.3.10_qbz5n2kfra8p0\LocalCache\local-packages\Python310\site-packages\pandas\core\indexes\base.py", line 3802, in get_loc
    return self._engine.get_loc(casted_key)
  File "pandas\_libs\index.pyx", line 516, in pandas._libs.index.DatetimeEngine.get_loc
  File "pandas\_libs\index.pyx", line 550, in pandas._libs.index.DatetimeEngine.get_loc
KeyError: Timestamp('2023-12-12 00:00:00')

The above exception was the direct cause of the following exception:

Traceback (most recent call last):
  File "C:\Users\mram\AppData\Local\Packages\PythonSoftwareFoundation.Python.3.10_qbz5n2kfra8p0\LocalCache\local-packages\Python310\site-packages\pandas\core\indexes\datetimes.py", line 736, in get_loc
    return Index.get_loc(self, key, method, tolerance)
  File "C:\Users\mram\AppData\Local\Packages\PythonSoftwareFoundation.Python.3.10_qbz5n2kfra8p0\LocalCache\local-packages\Python310\site-packages\pandas\core\indexes\base.py", line 3804, in get_loc
    raise KeyError(key) from err
KeyError: Timestamp('2023-12-12 00:00:00')

The above exception was the direct cause of the following exception:

Traceback (most recent call last):
  File "C:\Users\mram\AppData\Local\Packages\PythonSoftwareFoundation.Python.3.10_qbz5n2kfra8p0\LocalCache\local-packages\Python310\site-packages\pandasai\pipelines\smart_datalake_chat\code_execution.py", line 46, in execute
    result = pipeline_context.query_exec_tracker.execute_func(
  File "C:\Users\mram\AppData\Local\Packages\PythonSoftwareFoundation.Python.3.10_qbz5n2kfra8p0\LocalCache\local-packages\Python310\site-packages\pandasai\helpers\query_exec_tracker.py", line 128, in execute_func
    result = function(*args, **kwargs)
  File "C:\Users\mram\AppData\Local\Packages\PythonSoftwareFoundation.Python.3.10_qbz5n2kfra8p0\LocalCache\local-packages\Python310\site-packages\pandasai\helpers\code_manager.py", line 207, in execute_code
    exec(code_to_run, environment)
  File "<string>", line 1, in <module>
  File "C:\Users\mram\AppData\Local\Packages\PythonSoftwareFoundation.Python.3.10_qbz5n2kfra8p0\LocalCache\local-packages\Python310\site-packages\pandas\core\indexing.py", line 1067, in __getitem__
    return self._getitem_tuple(key)
  File "C:\Users\mram\AppData\Local\Packages\PythonSoftwareFoundation.Python.3.10_qbz5n2kfra8p0\LocalCache\local-packages\Python310\site-packages\pandas\core\indexing.py", line 1247, in _getitem_tuple
    return self._getitem_lowerdim(tup)
  File "C:\Users\mram\AppData\Local\Packages\PythonSoftwareFoundation.Python.3.10_qbz5n2kfra8p0\LocalCache\local-packages\Python310\site-packages\pandas\core\indexing.py", line 967, in _getitem_lowerdim
    section = self._getitem_axis(key, axis=i)
  File "C:\Users\mram\AppData\Local\Packages\PythonSoftwareFoundation.Python.3.10_qbz5n2kfra8p0\LocalCache\local-packages\Python310\site-packages\pandas\core\indexing.py", line 1312, in _getitem_axis
    return self._get_label(key, axis=axis)
  File "C:\Users\mram\AppData\Local\Packages\PythonSoftwareFoundation.Python.3.10_qbz5n2kfra8p0\LocalCache\local-packages\Python310\site-packages\pandas\core\indexing.py", line 1260, in _get_label
    return self.obj.xs(label, axis=axis)
  File "C:\Users\mram\AppData\Local\Packages\PythonSoftwareFoundation.Python.3.10_qbz5n2kfra8p0\LocalCache\local-packages\Python310\site-packages\pandas\core\generic.py", line 4056, in xs
    loc = index.get_loc(key)
  File "C:\Users\mram\AppData\Local\Packages\PythonSoftwareFoundation.Python.3.10_qbz5n2kfra8p0\LocalCache\local-packages\Python310\site-packages\pandas\core\indexes\datetimes.py", line 738, in get_loc
    raise KeyError(orig_key) from err
KeyError: '2023-12-12'
. Retrying
2024-01-13 17:52:59 [INFO] Using prompt: <dataframe>
dfs[0]:21x6
Open,High,Low,Close,Adj Close,Volume
44.08000183105469,44.720001220703125,43.33000183105469,44.56999969482422,44.56999969482422,35216100
45.939998626708984,47.27000045776367,45.66999816894531,46.15999984741211,46.15999984741211,84553800
45.0099983215332,47.06999969482422,44.650001525878906,45.18000030517578,45.18000030517578,70620800
</dataframe>

The user asked the following question:
Q: What was the price on 2023-12-12?

You generated this python code:
# TODO: import the required dependencies
import pandas as pd

# Write code here
price = dfs[0].loc['2023-12-12', 'Close']

# Declare result var
result = {
    "type": "number",
    "value": price
}

It fails with the following error:
Traceback (most recent call last):
  File "pandas\_libs\index.pyx", line 548, in pandas._libs.index.DatetimeEngine.get_loc
  File "pandas\_libs\hashtable_class_helper.pxi", line 2263, in pandas._libs.hashtable.Int64HashTable.get_item
  File "pandas\_libs\hashtable_class_helper.pxi", line 2273, in pandas._libs.hashtable.Int64HashTable.get_item
KeyError: 1702339200000000000

During handling of the above exception, another exception occurred:

Traceback (most recent call last):
  File "C:\Users\mram\AppData\Local\Packages\PythonSoftwareFoundation.Python.3.10_qbz5n2kfra8p0\LocalCache\local-packages\Python310\site-packages\pandas\core\indexes\base.py", line 3802, in get_loc
    return self._engine.get_loc(casted_key)
  File "pandas\_libs\index.pyx", line 516, in pandas._libs.index.DatetimeEngine.get_loc
  File "pandas\_libs\index.pyx", line 550, in pandas._libs.index.DatetimeEngine.get_loc
KeyError: Timestamp('2023-12-12 00:00:00')

The above exception was the direct cause of the following exception:

Traceback (most recent call last):
  File "C:\Users\mram\AppData\Local\Packages\PythonSoftwareFoundation.Python.3.10_qbz5n2kfra8p0\LocalCache\local-packages\Python310\site-packages\pandas\core\indexes\datetimes.py", line 736, in get_loc
    return Index.get_loc(self, key, method, tolerance)
  File "C:\Users\mram\AppData\Local\Packages\PythonSoftwareFoundation.Python.3.10_qbz5n2kfra8p0\LocalCache\local-packages\Python310\site-packages\pandas\core\indexes\base.py", line 3804, in get_loc
    raise KeyError(key) from err
KeyError: Timestamp('2023-12-12 00:00:00')

The above exception was the direct cause of the following exception:

Traceback (most recent call last):
  File "C:\Users\mram\AppData\Local\Packages\PythonSoftwareFoundation.Python.3.10_qbz5n2kfra8p0\LocalCache\local-packages\Python310\site-packages\pandasai\pipelines\smart_datalake_chat\code_execution.py", line 46, in execute
    result = pipeline_context.query_exec_tracker.execute_func(
  File "C:\Users\mram\AppData\Local\Packages\PythonSoftwareFoundation.Python.3.10_qbz5n2kfra8p0\LocalCache\local-packages\Python310\site-packages\pandasai\helpers\query_exec_tracker.py", line 128, in execute_func
    result = function(*args, **kwargs)
  File "C:\Users\mram\AppData\Local\Packages\PythonSoftwareFoundation.Python.3.10_qbz5n2kfra8p0\LocalCache\local-packages\Python310\site-packages\pandasai\helpers\code_manager.py", line 207, in execute_code
    exec(code_to_run, environment)
  File "<string>", line 1, in <module>
  File "C:\Users\mram\AppData\Local\Packages\PythonSoftwareFoundation.Python.3.10_qbz5n2kfra8p0\LocalCache\local-packages\Python310\site-packages\pandas\core\indexing.py", line 1067, in __getitem__
    return self._getitem_tuple(key)
  File "C:\Users\mram\AppData\Local\Packages\PythonSoftwareFoundation.Python.3.10_qbz5n2kfra8p0\LocalCache\local-packages\Python310\site-packages\pandas\core\indexing.py", line 1247, in _getitem_tuple
    return self._getitem_lowerdim(tup)
  File "C:\Users\mram\AppData\Local\Packages\PythonSoftwareFoundation.Python.3.10_qbz5n2kfra8p0\LocalCache\local-packages\Python310\site-packages\pandas\core\indexing.py", line 967, in _getitem_lowerdim
    section = self._getitem_axis(key, axis=i)
  File "C:\Users\mram\AppData\Local\Packages\PythonSoftwareFoundation.Python.3.10_qbz5n2kfra8p0\LocalCache\local-packages\Python310\site-packages\pandas\core\indexing.py", line 1312, in _getitem_axis
    return self._get_label(key, axis=axis)
  File "C:\Users\mram\AppData\Local\Packages\PythonSoftwareFoundation.Python.3.10_qbz5n2kfra8p0\LocalCache\local-packages\Python310\site-packages\pandas\core\indexing.py", line 1260, in _get_label
    return self.obj.xs(label, axis=axis)
  File "C:\Users\mram\AppData\Local\Packages\PythonSoftwareFoundation.Python.3.10_qbz5n2kfra8p0\LocalCache\local-packages\Python310\site-packages\pandas\core\generic.py", line 4056, in xs
    loc = index.get_loc(key)
  File "C:\Users\mram\AppData\Local\Packages\PythonSoftwareFoundation.Python.3.10_qbz5n2kfra8p0\LocalCache\local-packages\Python310\site-packages\pandas\core\indexes\datetimes.py", line 738, in get_loc
    raise KeyError(orig_key) from err
KeyError: '2023-12-12'


Fix the python code above and return the new python code:
2024-01-13 17:53:01 [INFO] HTTP Request: POST https://api.openai.com/v1/chat/completions "HTTP/1.1 200 OK"
2024-01-13 17:53:01 [INFO] Saving charts to C:\Users\mram\OneDrive - Intel Corporation\Python\OpenAI\ChatFun\exports\charts\temp_chart.png
2024-01-13 17:53:01 [INFO] 
Code running:
```
price = dfs[0].loc['2023-12-12', 'Close']
result = {'type': 'number', 'value': price}
result
        ```
2024-01-13 17:53:01 [WARNING] Failed to execute code with a correction framework [retry number: 2]
2024-01-13 17:53:01 [ERROR] Failed with error: Traceback (most recent call last):
  File "pandas\_libs\index.pyx", line 548, in pandas._libs.index.DatetimeEngine.get_loc
  File "pandas\_libs\hashtable_class_helper.pxi", line 2263, in pandas._libs.hashtable.Int64HashTable.get_item
  File "pandas\_libs\hashtable_class_helper.pxi", line 2273, in pandas._libs.hashtable.Int64HashTable.get_item
KeyError: 1702339200000000000

During handling of the above exception, another exception occurred:

Traceback (most recent call last):
  File "C:\Users\mram\AppData\Local\Packages\PythonSoftwareFoundation.Python.3.10_qbz5n2kfra8p0\LocalCache\local-packages\Python310\site-packages\pandas\core\indexes\base.py", line 3802, in get_loc
    return self._engine.get_loc(casted_key)
  File "pandas\_libs\index.pyx", line 516, in pandas._libs.index.DatetimeEngine.get_loc
  File "pandas\_libs\index.pyx", line 550, in pandas._libs.index.DatetimeEngine.get_loc
KeyError: Timestamp('2023-12-12 00:00:00')

The above exception was the direct cause of the following exception:

Traceback (most recent call last):
  File "C:\Users\mram\AppData\Local\Packages\PythonSoftwareFoundation.Python.3.10_qbz5n2kfra8p0\LocalCache\local-packages\Python310\site-packages\pandas\core\indexes\datetimes.py", line 736, in get_loc
    return Index.get_loc(self, key, method, tolerance)
  File "C:\Users\mram\AppData\Local\Packages\PythonSoftwareFoundation.Python.3.10_qbz5n2kfra8p0\LocalCache\local-packages\Python310\site-packages\pandas\core\indexes\base.py", line 3804, in get_loc
    raise KeyError(key) from err
KeyError: Timestamp('2023-12-12 00:00:00')

The above exception was the direct cause of the following exception:

Traceback (most recent call last):
  File "C:\Users\mram\AppData\Local\Packages\PythonSoftwareFoundation.Python.3.10_qbz5n2kfra8p0\LocalCache\local-packages\Python310\site-packages\pandasai\pipelines\smart_datalake_chat\code_execution.py", line 46, in execute
    result = pipeline_context.query_exec_tracker.execute_func(
  File "C:\Users\mram\AppData\Local\Packages\PythonSoftwareFoundation.Python.3.10_qbz5n2kfra8p0\LocalCache\local-packages\Python310\site-packages\pandasai\helpers\query_exec_tracker.py", line 128, in execute_func
    result = function(*args, **kwargs)
  File "C:\Users\mram\AppData\Local\Packages\PythonSoftwareFoundation.Python.3.10_qbz5n2kfra8p0\LocalCache\local-packages\Python310\site-packages\pandasai\helpers\code_manager.py", line 207, in execute_code
    exec(code_to_run, environment)
  File "<string>", line 1, in <module>
  File "C:\Users\mram\AppData\Local\Packages\PythonSoftwareFoundation.Python.3.10_qbz5n2kfra8p0\LocalCache\local-packages\Python310\site-packages\pandas\core\indexing.py", line 1067, in __getitem__
    return self._getitem_tuple(key)
  File "C:\Users\mram\AppData\Local\Packages\PythonSoftwareFoundation.Python.3.10_qbz5n2kfra8p0\LocalCache\local-packages\Python310\site-packages\pandas\core\indexing.py", line 1247, in _getitem_tuple
    return self._getitem_lowerdim(tup)
  File "C:\Users\mram\AppData\Local\Packages\PythonSoftwareFoundation.Python.3.10_qbz5n2kfra8p0\LocalCache\local-packages\Python310\site-packages\pandas\core\indexing.py", line 967, in _getitem_lowerdim
    section = self._getitem_axis(key, axis=i)
  File "C:\Users\mram\AppData\Local\Packages\PythonSoftwareFoundation.Python.3.10_qbz5n2kfra8p0\LocalCache\local-packages\Python310\site-packages\pandas\core\indexing.py", line 1312, in _getitem_axis
    return self._get_label(key, axis=axis)
  File "C:\Users\mram\AppData\Local\Packages\PythonSoftwareFoundation.Python.3.10_qbz5n2kfra8p0\LocalCache\local-packages\Python310\site-packages\pandas\core\indexing.py", line 1260, in _get_label
    return self.obj.xs(label, axis=axis)
  File "C:\Users\mram\AppData\Local\Packages\PythonSoftwareFoundation.Python.3.10_qbz5n2kfra8p0\LocalCache\local-packages\Python310\site-packages\pandas\core\generic.py", line 4056, in xs
    loc = index.get_loc(key)
  File "C:\Users\mram\AppData\Local\Packages\PythonSoftwareFoundation.Python.3.10_qbz5n2kfra8p0\LocalCache\local-packages\Python310\site-packages\pandas\core\indexes\datetimes.py", line 738, in get_loc
    raise KeyError(orig_key) from err
KeyError: '2023-12-12'
. Retrying
2024-01-13 17:53:01 [INFO] Using prompt: <dataframe>
dfs[0]:21x6
Open,High,Low,Close,Adj Close,Volume
44.08000183105469,44.720001220703125,43.33000183105469,44.56999969482422,44.56999969482422,35216100
45.939998626708984,47.27000045776367,45.66999816894531,46.15999984741211,46.15999984741211,84553800
45.0099983215332,47.06999969482422,44.650001525878906,45.18000030517578,45.18000030517578,70620800
</dataframe>

The user asked the following question:
Q: What was the price on 2023-12-12?

You generated this python code:
# TODO: import the required dependencies
import pandas as pd

# Write code here
price = dfs[0].loc['2023-12-12', 'Close']

# Declare result var
result = {
    "type": "number",
    "value": price
}

It fails with the following error:
Traceback (most recent call last):
  File "pandas\_libs\index.pyx", line 548, in pandas._libs.index.DatetimeEngine.get_loc
  File "pandas\_libs\hashtable_class_helper.pxi", line 2263, in pandas._libs.hashtable.Int64HashTable.get_item
  File "pandas\_libs\hashtable_class_helper.pxi", line 2273, in pandas._libs.hashtable.Int64HashTable.get_item
KeyError: 1702339200000000000

During handling of the above exception, another exception occurred:

Traceback (most recent call last):
  File "C:\Users\mram\AppData\Local\Packages\PythonSoftwareFoundation.Python.3.10_qbz5n2kfra8p0\LocalCache\local-packages\Python310\site-packages\pandas\core\indexes\base.py", line 3802, in get_loc
    return self._engine.get_loc(casted_key)
  File "pandas\_libs\index.pyx", line 516, in pandas._libs.index.DatetimeEngine.get_loc
  File "pandas\_libs\index.pyx", line 550, in pandas._libs.index.DatetimeEngine.get_loc
KeyError: Timestamp('2023-12-12 00:00:00')

The above exception was the direct cause of the following exception:

Traceback (most recent call last):
  File "C:\Users\mram\AppData\Local\Packages\PythonSoftwareFoundation.Python.3.10_qbz5n2kfra8p0\LocalCache\local-packages\Python310\site-packages\pandas\core\indexes\datetimes.py", line 736, in get_loc
    return Index.get_loc(self, key, method, tolerance)
  File "C:\Users\mram\AppData\Local\Packages\PythonSoftwareFoundation.Python.3.10_qbz5n2kfra8p0\LocalCache\local-packages\Python310\site-packages\pandas\core\indexes\base.py", line 3804, in get_loc
    raise KeyError(key) from err
KeyError: Timestamp('2023-12-12 00:00:00')

The above exception was the direct cause of the following exception:

Traceback (most recent call last):
  File "C:\Users\mram\AppData\Local\Packages\PythonSoftwareFoundation.Python.3.10_qbz5n2kfra8p0\LocalCache\local-packages\Python310\site-packages\pandasai\pipelines\smart_datalake_chat\code_execution.py", line 46, in execute
    result = pipeline_context.query_exec_tracker.execute_func(
  File "C:\Users\mram\AppData\Local\Packages\PythonSoftwareFoundation.Python.3.10_qbz5n2kfra8p0\LocalCache\local-packages\Python310\site-packages\pandasai\helpers\query_exec_tracker.py", line 128, in execute_func
    result = function(*args, **kwargs)
  File "C:\Users\mram\AppData\Local\Packages\PythonSoftwareFoundation.Python.3.10_qbz5n2kfra8p0\LocalCache\local-packages\Python310\site-packages\pandasai\helpers\code_manager.py", line 207, in execute_code
    exec(code_to_run, environment)
  File "<string>", line 1, in <module>
  File "C:\Users\mram\AppData\Local\Packages\PythonSoftwareFoundation.Python.3.10_qbz5n2kfra8p0\LocalCache\local-packages\Python310\site-packages\pandas\core\indexing.py", line 1067, in __getitem__
    return self._getitem_tuple(key)
  File "C:\Users\mram\AppData\Local\Packages\PythonSoftwareFoundation.Python.3.10_qbz5n2kfra8p0\LocalCache\local-packages\Python310\site-packages\pandas\core\indexing.py", line 1247, in _getitem_tuple
    return self._getitem_lowerdim(tup)
  File "C:\Users\mram\AppData\Local\Packages\PythonSoftwareFoundation.Python.3.10_qbz5n2kfra8p0\LocalCache\local-packages\Python310\site-packages\pandas\core\indexing.py", line 967, in _getitem_lowerdim
    section = self._getitem_axis(key, axis=i)
  File "C:\Users\mram\AppData\Local\Packages\PythonSoftwareFoundation.Python.3.10_qbz5n2kfra8p0\LocalCache\local-packages\Python310\site-packages\pandas\core\indexing.py", line 1312, in _getitem_axis
    return self._get_label(key, axis=axis)
  File "C:\Users\mram\AppData\Local\Packages\PythonSoftwareFoundation.Python.3.10_qbz5n2kfra8p0\LocalCache\local-packages\Python310\site-packages\pandas\core\indexing.py", line 1260, in _get_label
    return self.obj.xs(label, axis=axis)
  File "C:\Users\mram\AppData\Local\Packages\PythonSoftwareFoundation.Python.3.10_qbz5n2kfra8p0\LocalCache\local-packages\Python310\site-packages\pandas\core\generic.py", line 4056, in xs
    loc = index.get_loc(key)
  File "C:\Users\mram\AppData\Local\Packages\PythonSoftwareFoundation.Python.3.10_qbz5n2kfra8p0\LocalCache\local-packages\Python310\site-packages\pandas\core\indexes\datetimes.py", line 738, in get_loc
    raise KeyError(orig_key) from err
KeyError: '2023-12-12'


Fix the python code above and return the new python code:
2024-01-13 17:53:03 [INFO] HTTP Request: POST https://api.openai.com/v1/chat/completions "HTTP/1.1 200 OK"
2024-01-13 17:53:03 [INFO] Saving charts to C:\Users\mram\OneDrive - Intel Corporation\Python\OpenAI\ChatFun\exports\charts\temp_chart.png
2024-01-13 17:53:03 [INFO] 
Code running:
```
price = dfs[0].loc['2023-12-12', 'Close']
result = {'type': 'number', 'value': price}
result
        ```
2024-01-13 17:53:03 [ERROR] Pipeline failed on step 4: '2023-12-12'
2024-01-13 17:53:39 [INFO] Question: What was the price on 2023-12-13?
2024-01-13 17:53:39 [INFO] Running PandasAI with openai LLM...
2024-01-13 17:53:39 [INFO] Prompt ID: 802dd449-f94b-411c-9f1e-8c47daf1cc21
2024-01-13 17:53:39 [INFO] Executing Step 0: CacheLookup
2024-01-13 17:53:39 [INFO] Executing Step 1: PromptGeneration
2024-01-13 17:53:39 [INFO] Using prompt: <dataframe>
dfs[0]:21x6
Open,High,Low,Close,Adj Close,Volume
44.08000183105469,44.720001220703125,43.33000183105469,44.56999969482422,44.56999969482422,35216100
45.0099983215332,47.06999969482422,44.650001525878906,45.18000030517578,45.18000030517578,70620800
45.939998626708984,47.27000045776367,45.66999816894531,46.15999984741211,46.15999984741211,84553800
</dataframe>




Update this initial code:
```python
# TODO: import the required dependencies
import pandas as pd

# Write code here

# Declare result var: type (possible values "string", "number", "dataframe", "plot"). Examples: { "type": "string", "value": f"The highest salary is {highest_salary}." } or { "type": "number", "value": 125 } or { "type": "dataframe", "value": pd.DataFrame({...}) } or { "type": "plot", "value": "temp_chart.png" }
```

Q: What was the price on 2023-12-13?
Variable `dfs: list[pd.DataFrame]` is already declared.

At the end, declare "result" variable as a dictionary of type and value.



Generate python code and return full updated code:
2024-01-13 17:53:39 [INFO] Executing Step 2: CodeGenerator
2024-01-13 17:53:42 [INFO] HTTP Request: POST https://api.openai.com/v1/chat/completions "HTTP/1.1 200 OK"
2024-01-13 17:53:42 [INFO] Code generated:
            ```
            # TODO: import the required dependencies
import pandas as pd

# Write code here
price = dfs[0].loc['2023-12-13', 'Close']

# Declare result var
result = {
    "type": "number",
    "value": price
}
            ```
            
2024-01-13 17:53:42 [INFO] Executing Step 3: CachePopulation
2024-01-13 17:53:42 [INFO] Executing Step 4: CodeExecution
2024-01-13 17:53:42 [INFO] Saving charts to C:\Users\mram\OneDrive - Intel Corporation\Python\OpenAI\ChatFun\exports\charts\temp_chart.png
2024-01-13 17:53:42 [INFO] 
Code running:
```
price = dfs[0].loc['2023-12-13', 'Close']
result = {'type': 'number', 'value': price}
        ```
2024-01-13 17:53:42 [INFO] Executing Step 5: ResultValidation
2024-01-13 17:53:42 [INFO] Answer: {'type': 'number', 'value': 44.56999969482422}
2024-01-13 17:53:42 [INFO] Executed in: 2.6779556274414062s
2024-01-13 17:53:42 [INFO] Executing Step 6: ResultParsing
2024-01-13 17:57:02 [INFO] Question: What was the price on 2024-01-01?
2024-01-13 17:57:02 [INFO] Running PandasAI with openai LLM...
2024-01-13 17:57:02 [INFO] Prompt ID: d0ddbcfa-0a02-423d-8008-c4fc45fdec57
2024-01-13 17:57:02 [INFO] Executing Step 0: CacheLookup
2024-01-13 17:57:02 [INFO] Executing Step 1: PromptGeneration
2024-01-13 17:57:02 [INFO] Using prompt: <dataframe>
dfs[0]:21x6
Open,High,Low,Close,Adj Close,Volume
44.08000183105469,44.720001220703125,43.33000183105469,44.56999969482422,44.56999969482422,35216100
45.939998626708984,47.27000045776367,45.66999816894531,46.15999984741211,46.15999984741211,84553800
45.0099983215332,47.06999969482422,44.650001525878906,45.18000030517578,45.18000030517578,70620800
</dataframe>




Update this initial code:
```python
# TODO: import the required dependencies
import pandas as pd

# Write code here

# Declare result var: type (possible values "string", "number", "dataframe", "plot"). Examples: { "type": "string", "value": f"The highest salary is {highest_salary}." } or { "type": "number", "value": 125 } or { "type": "dataframe", "value": pd.DataFrame({...}) } or { "type": "plot", "value": "temp_chart.png" }
```

Q: What was the price on 2024-01-01?
Variable `dfs: list[pd.DataFrame]` is already declared.

At the end, declare "result" variable as a dictionary of type and value.



Generate python code and return full updated code:
2024-01-13 17:57:02 [INFO] Executing Step 2: CodeGenerator
2024-01-13 17:57:04 [INFO] HTTP Request: POST https://api.openai.com/v1/chat/completions "HTTP/1.1 200 OK"
2024-01-13 17:57:04 [INFO] Code generated:
            ```
            # TODO: import the required dependencies
import pandas as pd

# Write code here
price = dfs[0].loc['2024-01-01', 'Close']

# Declare result var
result = {
    "type": "number",
    "value": price
}
            ```
            
2024-01-13 17:57:04 [INFO] Executing Step 3: CachePopulation
2024-01-13 17:57:04 [INFO] Executing Step 4: CodeExecution
2024-01-13 17:57:04 [INFO] Saving charts to C:\Users\mram\OneDrive - Intel Corporation\Python\OpenAI\ChatFun\exports\charts\temp_chart.png
2024-01-13 17:57:04 [INFO] 
Code running:
```
price = dfs[0].loc['2024-01-01', 'Close']
result = {'type': 'number', 'value': price}
        ```
2024-01-13 17:57:04 [WARNING] Failed to execute code with a correction framework [retry number: 1]
2024-01-13 17:57:04 [ERROR] Failed with error: Traceback (most recent call last):
  File "pandas\_libs\index.pyx", line 548, in pandas._libs.index.DatetimeEngine.get_loc
  File "pandas\_libs\hashtable_class_helper.pxi", line 2263, in pandas._libs.hashtable.Int64HashTable.get_item
  File "pandas\_libs\hashtable_class_helper.pxi", line 2273, in pandas._libs.hashtable.Int64HashTable.get_item
KeyError: 1704067200000000000

During handling of the above exception, another exception occurred:

Traceback (most recent call last):
  File "C:\Users\mram\AppData\Local\Packages\PythonSoftwareFoundation.Python.3.10_qbz5n2kfra8p0\LocalCache\local-packages\Python310\site-packages\pandas\core\indexes\base.py", line 3802, in get_loc
    return self._engine.get_loc(casted_key)
  File "pandas\_libs\index.pyx", line 516, in pandas._libs.index.DatetimeEngine.get_loc
  File "pandas\_libs\index.pyx", line 550, in pandas._libs.index.DatetimeEngine.get_loc
KeyError: Timestamp('2024-01-01 00:00:00')

The above exception was the direct cause of the following exception:

Traceback (most recent call last):
  File "C:\Users\mram\AppData\Local\Packages\PythonSoftwareFoundation.Python.3.10_qbz5n2kfra8p0\LocalCache\local-packages\Python310\site-packages\pandas\core\indexes\datetimes.py", line 736, in get_loc
    return Index.get_loc(self, key, method, tolerance)
  File "C:\Users\mram\AppData\Local\Packages\PythonSoftwareFoundation.Python.3.10_qbz5n2kfra8p0\LocalCache\local-packages\Python310\site-packages\pandas\core\indexes\base.py", line 3804, in get_loc
    raise KeyError(key) from err
KeyError: Timestamp('2024-01-01 00:00:00')

The above exception was the direct cause of the following exception:

Traceback (most recent call last):
  File "C:\Users\mram\AppData\Local\Packages\PythonSoftwareFoundation.Python.3.10_qbz5n2kfra8p0\LocalCache\local-packages\Python310\site-packages\pandasai\pipelines\smart_datalake_chat\code_execution.py", line 46, in execute
    result = pipeline_context.query_exec_tracker.execute_func(
  File "C:\Users\mram\AppData\Local\Packages\PythonSoftwareFoundation.Python.3.10_qbz5n2kfra8p0\LocalCache\local-packages\Python310\site-packages\pandasai\helpers\query_exec_tracker.py", line 128, in execute_func
    result = function(*args, **kwargs)
  File "C:\Users\mram\AppData\Local\Packages\PythonSoftwareFoundation.Python.3.10_qbz5n2kfra8p0\LocalCache\local-packages\Python310\site-packages\pandasai\helpers\code_manager.py", line 207, in execute_code
    exec(code_to_run, environment)
  File "<string>", line 1, in <module>
  File "C:\Users\mram\AppData\Local\Packages\PythonSoftwareFoundation.Python.3.10_qbz5n2kfra8p0\LocalCache\local-packages\Python310\site-packages\pandas\core\indexing.py", line 1067, in __getitem__
    return self._getitem_tuple(key)
  File "C:\Users\mram\AppData\Local\Packages\PythonSoftwareFoundation.Python.3.10_qbz5n2kfra8p0\LocalCache\local-packages\Python310\site-packages\pandas\core\indexing.py", line 1247, in _getitem_tuple
    return self._getitem_lowerdim(tup)
  File "C:\Users\mram\AppData\Local\Packages\PythonSoftwareFoundation.Python.3.10_qbz5n2kfra8p0\LocalCache\local-packages\Python310\site-packages\pandas\core\indexing.py", line 967, in _getitem_lowerdim
    section = self._getitem_axis(key, axis=i)
  File "C:\Users\mram\AppData\Local\Packages\PythonSoftwareFoundation.Python.3.10_qbz5n2kfra8p0\LocalCache\local-packages\Python310\site-packages\pandas\core\indexing.py", line 1312, in _getitem_axis
    return self._get_label(key, axis=axis)
  File "C:\Users\mram\AppData\Local\Packages\PythonSoftwareFoundation.Python.3.10_qbz5n2kfra8p0\LocalCache\local-packages\Python310\site-packages\pandas\core\indexing.py", line 1260, in _get_label
    return self.obj.xs(label, axis=axis)
  File "C:\Users\mram\AppData\Local\Packages\PythonSoftwareFoundation.Python.3.10_qbz5n2kfra8p0\LocalCache\local-packages\Python310\site-packages\pandas\core\generic.py", line 4056, in xs
    loc = index.get_loc(key)
  File "C:\Users\mram\AppData\Local\Packages\PythonSoftwareFoundation.Python.3.10_qbz5n2kfra8p0\LocalCache\local-packages\Python310\site-packages\pandas\core\indexes\datetimes.py", line 738, in get_loc
    raise KeyError(orig_key) from err
KeyError: '2024-01-01'
. Retrying
2024-01-13 17:57:04 [INFO] Using prompt: <dataframe>
dfs[0]:21x6
Open,High,Low,Close,Adj Close,Volume
44.08000183105469,44.720001220703125,43.33000183105469,44.56999969482422,44.56999969482422,35216100
45.939998626708984,47.27000045776367,45.66999816894531,46.15999984741211,46.15999984741211,84553800
45.0099983215332,47.06999969482422,44.650001525878906,45.18000030517578,45.18000030517578,70620800
</dataframe>

The user asked the following question:
Q: What was the price on 2024-01-01?

You generated this python code:
# TODO: import the required dependencies
import pandas as pd

# Write code here
price = dfs[0].loc['2024-01-01', 'Close']

# Declare result var
result = {
    "type": "number",
    "value": price
}

It fails with the following error:
Traceback (most recent call last):
  File "pandas\_libs\index.pyx", line 548, in pandas._libs.index.DatetimeEngine.get_loc
  File "pandas\_libs\hashtable_class_helper.pxi", line 2263, in pandas._libs.hashtable.Int64HashTable.get_item
  File "pandas\_libs\hashtable_class_helper.pxi", line 2273, in pandas._libs.hashtable.Int64HashTable.get_item
KeyError: 1704067200000000000

During handling of the above exception, another exception occurred:

Traceback (most recent call last):
  File "C:\Users\mram\AppData\Local\Packages\PythonSoftwareFoundation.Python.3.10_qbz5n2kfra8p0\LocalCache\local-packages\Python310\site-packages\pandas\core\indexes\base.py", line 3802, in get_loc
    return self._engine.get_loc(casted_key)
  File "pandas\_libs\index.pyx", line 516, in pandas._libs.index.DatetimeEngine.get_loc
  File "pandas\_libs\index.pyx", line 550, in pandas._libs.index.DatetimeEngine.get_loc
KeyError: Timestamp('2024-01-01 00:00:00')

The above exception was the direct cause of the following exception:

Traceback (most recent call last):
  File "C:\Users\mram\AppData\Local\Packages\PythonSoftwareFoundation.Python.3.10_qbz5n2kfra8p0\LocalCache\local-packages\Python310\site-packages\pandas\core\indexes\datetimes.py", line 736, in get_loc
    return Index.get_loc(self, key, method, tolerance)
  File "C:\Users\mram\AppData\Local\Packages\PythonSoftwareFoundation.Python.3.10_qbz5n2kfra8p0\LocalCache\local-packages\Python310\site-packages\pandas\core\indexes\base.py", line 3804, in get_loc
    raise KeyError(key) from err
KeyError: Timestamp('2024-01-01 00:00:00')

The above exception was the direct cause of the following exception:

Traceback (most recent call last):
  File "C:\Users\mram\AppData\Local\Packages\PythonSoftwareFoundation.Python.3.10_qbz5n2kfra8p0\LocalCache\local-packages\Python310\site-packages\pandasai\pipelines\smart_datalake_chat\code_execution.py", line 46, in execute
    result = pipeline_context.query_exec_tracker.execute_func(
  File "C:\Users\mram\AppData\Local\Packages\PythonSoftwareFoundation.Python.3.10_qbz5n2kfra8p0\LocalCache\local-packages\Python310\site-packages\pandasai\helpers\query_exec_tracker.py", line 128, in execute_func
    result = function(*args, **kwargs)
  File "C:\Users\mram\AppData\Local\Packages\PythonSoftwareFoundation.Python.3.10_qbz5n2kfra8p0\LocalCache\local-packages\Python310\site-packages\pandasai\helpers\code_manager.py", line 207, in execute_code
    exec(code_to_run, environment)
  File "<string>", line 1, in <module>
  File "C:\Users\mram\AppData\Local\Packages\PythonSoftwareFoundation.Python.3.10_qbz5n2kfra8p0\LocalCache\local-packages\Python310\site-packages\pandas\core\indexing.py", line 1067, in __getitem__
    return self._getitem_tuple(key)
  File "C:\Users\mram\AppData\Local\Packages\PythonSoftwareFoundation.Python.3.10_qbz5n2kfra8p0\LocalCache\local-packages\Python310\site-packages\pandas\core\indexing.py", line 1247, in _getitem_tuple
    return self._getitem_lowerdim(tup)
  File "C:\Users\mram\AppData\Local\Packages\PythonSoftwareFoundation.Python.3.10_qbz5n2kfra8p0\LocalCache\local-packages\Python310\site-packages\pandas\core\indexing.py", line 967, in _getitem_lowerdim
    section = self._getitem_axis(key, axis=i)
  File "C:\Users\mram\AppData\Local\Packages\PythonSoftwareFoundation.Python.3.10_qbz5n2kfra8p0\LocalCache\local-packages\Python310\site-packages\pandas\core\indexing.py", line 1312, in _getitem_axis
    return self._get_label(key, axis=axis)
  File "C:\Users\mram\AppData\Local\Packages\PythonSoftwareFoundation.Python.3.10_qbz5n2kfra8p0\LocalCache\local-packages\Python310\site-packages\pandas\core\indexing.py", line 1260, in _get_label
    return self.obj.xs(label, axis=axis)
  File "C:\Users\mram\AppData\Local\Packages\PythonSoftwareFoundation.Python.3.10_qbz5n2kfra8p0\LocalCache\local-packages\Python310\site-packages\pandas\core\generic.py", line 4056, in xs
    loc = index.get_loc(key)
  File "C:\Users\mram\AppData\Local\Packages\PythonSoftwareFoundation.Python.3.10_qbz5n2kfra8p0\LocalCache\local-packages\Python310\site-packages\pandas\core\indexes\datetimes.py", line 738, in get_loc
    raise KeyError(orig_key) from err
KeyError: '2024-01-01'


Fix the python code above and return the new python code:
2024-01-13 17:57:07 [INFO] HTTP Request: POST https://api.openai.com/v1/chat/completions "HTTP/1.1 200 OK"
2024-01-13 17:57:07 [INFO] Saving charts to C:\Users\mram\OneDrive - Intel Corporation\Python\OpenAI\ChatFun\exports\charts\temp_chart.png
2024-01-13 17:57:07 [INFO] 
Code running:
```
price = dfs[0].loc['2024-01-01', 'Close']
result = {'type': 'number', 'value': price}
result
        ```
2024-01-13 17:57:07 [WARNING] Failed to execute code with a correction framework [retry number: 2]
2024-01-13 17:57:07 [ERROR] Failed with error: Traceback (most recent call last):
  File "pandas\_libs\index.pyx", line 548, in pandas._libs.index.DatetimeEngine.get_loc
  File "pandas\_libs\hashtable_class_helper.pxi", line 2263, in pandas._libs.hashtable.Int64HashTable.get_item
  File "pandas\_libs\hashtable_class_helper.pxi", line 2273, in pandas._libs.hashtable.Int64HashTable.get_item
KeyError: 1704067200000000000

During handling of the above exception, another exception occurred:

Traceback (most recent call last):
  File "C:\Users\mram\AppData\Local\Packages\PythonSoftwareFoundation.Python.3.10_qbz5n2kfra8p0\LocalCache\local-packages\Python310\site-packages\pandas\core\indexes\base.py", line 3802, in get_loc
    return self._engine.get_loc(casted_key)
  File "pandas\_libs\index.pyx", line 516, in pandas._libs.index.DatetimeEngine.get_loc
  File "pandas\_libs\index.pyx", line 550, in pandas._libs.index.DatetimeEngine.get_loc
KeyError: Timestamp('2024-01-01 00:00:00')

The above exception was the direct cause of the following exception:

Traceback (most recent call last):
  File "C:\Users\mram\AppData\Local\Packages\PythonSoftwareFoundation.Python.3.10_qbz5n2kfra8p0\LocalCache\local-packages\Python310\site-packages\pandas\core\indexes\datetimes.py", line 736, in get_loc
    return Index.get_loc(self, key, method, tolerance)
  File "C:\Users\mram\AppData\Local\Packages\PythonSoftwareFoundation.Python.3.10_qbz5n2kfra8p0\LocalCache\local-packages\Python310\site-packages\pandas\core\indexes\base.py", line 3804, in get_loc
    raise KeyError(key) from err
KeyError: Timestamp('2024-01-01 00:00:00')

The above exception was the direct cause of the following exception:

Traceback (most recent call last):
  File "C:\Users\mram\AppData\Local\Packages\PythonSoftwareFoundation.Python.3.10_qbz5n2kfra8p0\LocalCache\local-packages\Python310\site-packages\pandasai\pipelines\smart_datalake_chat\code_execution.py", line 46, in execute
    result = pipeline_context.query_exec_tracker.execute_func(
  File "C:\Users\mram\AppData\Local\Packages\PythonSoftwareFoundation.Python.3.10_qbz5n2kfra8p0\LocalCache\local-packages\Python310\site-packages\pandasai\helpers\query_exec_tracker.py", line 128, in execute_func
    result = function(*args, **kwargs)
  File "C:\Users\mram\AppData\Local\Packages\PythonSoftwareFoundation.Python.3.10_qbz5n2kfra8p0\LocalCache\local-packages\Python310\site-packages\pandasai\helpers\code_manager.py", line 207, in execute_code
    exec(code_to_run, environment)
  File "<string>", line 1, in <module>
  File "C:\Users\mram\AppData\Local\Packages\PythonSoftwareFoundation.Python.3.10_qbz5n2kfra8p0\LocalCache\local-packages\Python310\site-packages\pandas\core\indexing.py", line 1067, in __getitem__
    return self._getitem_tuple(key)
  File "C:\Users\mram\AppData\Local\Packages\PythonSoftwareFoundation.Python.3.10_qbz5n2kfra8p0\LocalCache\local-packages\Python310\site-packages\pandas\core\indexing.py", line 1247, in _getitem_tuple
    return self._getitem_lowerdim(tup)
  File "C:\Users\mram\AppData\Local\Packages\PythonSoftwareFoundation.Python.3.10_qbz5n2kfra8p0\LocalCache\local-packages\Python310\site-packages\pandas\core\indexing.py", line 967, in _getitem_lowerdim
    section = self._getitem_axis(key, axis=i)
  File "C:\Users\mram\AppData\Local\Packages\PythonSoftwareFoundation.Python.3.10_qbz5n2kfra8p0\LocalCache\local-packages\Python310\site-packages\pandas\core\indexing.py", line 1312, in _getitem_axis
    return self._get_label(key, axis=axis)
  File "C:\Users\mram\AppData\Local\Packages\PythonSoftwareFoundation.Python.3.10_qbz5n2kfra8p0\LocalCache\local-packages\Python310\site-packages\pandas\core\indexing.py", line 1260, in _get_label
    return self.obj.xs(label, axis=axis)
  File "C:\Users\mram\AppData\Local\Packages\PythonSoftwareFoundation.Python.3.10_qbz5n2kfra8p0\LocalCache\local-packages\Python310\site-packages\pandas\core\generic.py", line 4056, in xs
    loc = index.get_loc(key)
  File "C:\Users\mram\AppData\Local\Packages\PythonSoftwareFoundation.Python.3.10_qbz5n2kfra8p0\LocalCache\local-packages\Python310\site-packages\pandas\core\indexes\datetimes.py", line 738, in get_loc
    raise KeyError(orig_key) from err
KeyError: '2024-01-01'
. Retrying
2024-01-13 17:57:07 [INFO] Using prompt: <dataframe>
dfs[0]:21x6
Open,High,Low,Close,Adj Close,Volume
44.08000183105469,44.720001220703125,43.33000183105469,44.56999969482422,44.56999969482422,35216100
45.939998626708984,47.27000045776367,45.66999816894531,46.15999984741211,46.15999984741211,84553800
45.0099983215332,47.06999969482422,44.650001525878906,45.18000030517578,45.18000030517578,70620800
</dataframe>

The user asked the following question:
Q: What was the price on 2024-01-01?

You generated this python code:
# TODO: import the required dependencies
import pandas as pd

# Write code here
price = dfs[0].loc['2024-01-01', 'Close']

# Declare result var
result = {
    "type": "number",
    "value": price
}

It fails with the following error:
Traceback (most recent call last):
  File "pandas\_libs\index.pyx", line 548, in pandas._libs.index.DatetimeEngine.get_loc
  File "pandas\_libs\hashtable_class_helper.pxi", line 2263, in pandas._libs.hashtable.Int64HashTable.get_item
  File "pandas\_libs\hashtable_class_helper.pxi", line 2273, in pandas._libs.hashtable.Int64HashTable.get_item
KeyError: 1704067200000000000

During handling of the above exception, another exception occurred:

Traceback (most recent call last):
  File "C:\Users\mram\AppData\Local\Packages\PythonSoftwareFoundation.Python.3.10_qbz5n2kfra8p0\LocalCache\local-packages\Python310\site-packages\pandas\core\indexes\base.py", line 3802, in get_loc
    return self._engine.get_loc(casted_key)
  File "pandas\_libs\index.pyx", line 516, in pandas._libs.index.DatetimeEngine.get_loc
  File "pandas\_libs\index.pyx", line 550, in pandas._libs.index.DatetimeEngine.get_loc
KeyError: Timestamp('2024-01-01 00:00:00')

The above exception was the direct cause of the following exception:

Traceback (most recent call last):
  File "C:\Users\mram\AppData\Local\Packages\PythonSoftwareFoundation.Python.3.10_qbz5n2kfra8p0\LocalCache\local-packages\Python310\site-packages\pandas\core\indexes\datetimes.py", line 736, in get_loc
    return Index.get_loc(self, key, method, tolerance)
  File "C:\Users\mram\AppData\Local\Packages\PythonSoftwareFoundation.Python.3.10_qbz5n2kfra8p0\LocalCache\local-packages\Python310\site-packages\pandas\core\indexes\base.py", line 3804, in get_loc
    raise KeyError(key) from err
KeyError: Timestamp('2024-01-01 00:00:00')

The above exception was the direct cause of the following exception:

Traceback (most recent call last):
  File "C:\Users\mram\AppData\Local\Packages\PythonSoftwareFoundation.Python.3.10_qbz5n2kfra8p0\LocalCache\local-packages\Python310\site-packages\pandasai\pipelines\smart_datalake_chat\code_execution.py", line 46, in execute
    result = pipeline_context.query_exec_tracker.execute_func(
  File "C:\Users\mram\AppData\Local\Packages\PythonSoftwareFoundation.Python.3.10_qbz5n2kfra8p0\LocalCache\local-packages\Python310\site-packages\pandasai\helpers\query_exec_tracker.py", line 128, in execute_func
    result = function(*args, **kwargs)
  File "C:\Users\mram\AppData\Local\Packages\PythonSoftwareFoundation.Python.3.10_qbz5n2kfra8p0\LocalCache\local-packages\Python310\site-packages\pandasai\helpers\code_manager.py", line 207, in execute_code
    exec(code_to_run, environment)
  File "<string>", line 1, in <module>
  File "C:\Users\mram\AppData\Local\Packages\PythonSoftwareFoundation.Python.3.10_qbz5n2kfra8p0\LocalCache\local-packages\Python310\site-packages\pandas\core\indexing.py", line 1067, in __getitem__
    return self._getitem_tuple(key)
  File "C:\Users\mram\AppData\Local\Packages\PythonSoftwareFoundation.Python.3.10_qbz5n2kfra8p0\LocalCache\local-packages\Python310\site-packages\pandas\core\indexing.py", line 1247, in _getitem_tuple
    return self._getitem_lowerdim(tup)
  File "C:\Users\mram\AppData\Local\Packages\PythonSoftwareFoundation.Python.3.10_qbz5n2kfra8p0\LocalCache\local-packages\Python310\site-packages\pandas\core\indexing.py", line 967, in _getitem_lowerdim
    section = self._getitem_axis(key, axis=i)
  File "C:\Users\mram\AppData\Local\Packages\PythonSoftwareFoundation.Python.3.10_qbz5n2kfra8p0\LocalCache\local-packages\Python310\site-packages\pandas\core\indexing.py", line 1312, in _getitem_axis
    return self._get_label(key, axis=axis)
  File "C:\Users\mram\AppData\Local\Packages\PythonSoftwareFoundation.Python.3.10_qbz5n2kfra8p0\LocalCache\local-packages\Python310\site-packages\pandas\core\indexing.py", line 1260, in _get_label
    return self.obj.xs(label, axis=axis)
  File "C:\Users\mram\AppData\Local\Packages\PythonSoftwareFoundation.Python.3.10_qbz5n2kfra8p0\LocalCache\local-packages\Python310\site-packages\pandas\core\generic.py", line 4056, in xs
    loc = index.get_loc(key)
  File "C:\Users\mram\AppData\Local\Packages\PythonSoftwareFoundation.Python.3.10_qbz5n2kfra8p0\LocalCache\local-packages\Python310\site-packages\pandas\core\indexes\datetimes.py", line 738, in get_loc
    raise KeyError(orig_key) from err
KeyError: '2024-01-01'


Fix the python code above and return the new python code:
2024-01-13 17:57:09 [INFO] HTTP Request: POST https://api.openai.com/v1/chat/completions "HTTP/1.1 200 OK"
2024-01-13 17:57:09 [INFO] Saving charts to C:\Users\mram\OneDrive - Intel Corporation\Python\OpenAI\ChatFun\exports\charts\temp_chart.png
2024-01-13 17:57:09 [INFO] 
Code running:
```
price = dfs[0].loc['2024-01-01', 'Close']
result = {'type': 'number', 'value': price}
result
        ```
2024-01-13 17:57:09 [ERROR] Pipeline failed on step 4: '2024-01-01'
2024-01-13 17:57:25 [INFO] Question: What was the price on 2024-01-02?
2024-01-13 17:57:25 [INFO] Running PandasAI with openai LLM...
2024-01-13 17:57:25 [INFO] Prompt ID: 84f2e1c4-ae27-40b1-9243-bfe8a21b044a
2024-01-13 17:57:25 [INFO] Executing Step 0: CacheLookup
2024-01-13 17:57:25 [INFO] Executing Step 1: PromptGeneration
2024-01-13 17:57:25 [INFO] Using prompt: <dataframe>
dfs[0]:21x6
Open,High,Low,Close,Adj Close,Volume
44.08000183105469,44.720001220703125,43.33000183105469,44.56999969482422,44.56999969482422,35216100
45.0099983215332,47.06999969482422,44.650001525878906,45.18000030517578,45.18000030517578,70620800
45.939998626708984,47.27000045776367,45.66999816894531,46.15999984741211,46.15999984741211,84553800
</dataframe>




Update this initial code:
```python
# TODO: import the required dependencies
import pandas as pd

# Write code here

# Declare result var: type (possible values "string", "number", "dataframe", "plot"). Examples: { "type": "string", "value": f"The highest salary is {highest_salary}." } or { "type": "number", "value": 125 } or { "type": "dataframe", "value": pd.DataFrame({...}) } or { "type": "plot", "value": "temp_chart.png" }
```

Q: What was the price on 2024-01-02?
Variable `dfs: list[pd.DataFrame]` is already declared.

At the end, declare "result" variable as a dictionary of type and value.



Generate python code and return full updated code:
2024-01-13 17:57:25 [INFO] Executing Step 2: CodeGenerator
2024-01-13 17:57:27 [INFO] HTTP Request: POST https://api.openai.com/v1/chat/completions "HTTP/1.1 200 OK"
2024-01-13 17:57:27 [INFO] Code generated:
            ```
            # TODO: import the required dependencies
import pandas as pd

# Write code here
price = dfs[0].loc['2024-01-02', 'Close']

# Declare result var
result = {
    "type": "number",
    "value": price
}
            ```
            
2024-01-13 17:57:27 [INFO] Executing Step 3: CachePopulation
2024-01-13 17:57:27 [INFO] Executing Step 4: CodeExecution
2024-01-13 17:57:27 [INFO] Saving charts to C:\Users\mram\OneDrive - Intel Corporation\Python\OpenAI\ChatFun\exports\charts\temp_chart.png
2024-01-13 17:57:27 [INFO] 
Code running:
```
price = dfs[0].loc['2024-01-02', 'Close']
result = {'type': 'number', 'value': price}
        ```
2024-01-13 17:57:27 [INFO] Executing Step 5: ResultValidation
2024-01-13 17:57:27 [INFO] Answer: {'type': 'number', 'value': 47.79999923706055}
2024-01-13 17:57:27 [INFO] Executed in: 2.598794937133789s
2024-01-13 17:57:27 [INFO] Executing Step 6: ResultParsing
2024-01-14 15:28:11 [ERROR] 
1 Failed download:
2024-01-14 15:28:11 [ERROR] ['INTC']: Exception('%ticker%: No price data found, symbol may be delisted (period=1mo)')
2024-01-15 12:54:10 [ERROR] 
1 Failed download:
2024-01-15 12:54:10 [ERROR] 
1 Failed download:
2024-01-15 12:54:10 [ERROR] ['INTC']: Exception('%ticker%: No price data found, symbol may be delisted (period=1mo)')
2024-01-15 12:54:10 [ERROR] ['INTC']: Exception('%ticker%: No price data found, symbol may be delisted (period=1mo)')
2024-01-16 12:00:29 [ERROR] 
1 Failed download:
2024-01-16 12:00:29 [ERROR] ['INTC']: Exception('%ticker%: No price data found, symbol may be delisted (period=1mo)')
2024-03-02 13:54:54 [INFO] Question: What was the price on 2024-01-01?
2024-03-02 13:54:54 [INFO] Running PandasAI with openai LLM...
2024-03-02 13:54:54 [INFO] Prompt ID: 5ff38e4e-1839-48f4-9fa1-2d532b0e277f
2024-03-02 13:54:54 [INFO] Executing Step 0: CacheLookup
2024-03-02 13:54:54 [INFO] Using cached response
2024-03-02 13:54:54 [INFO] Executing Step 1: PromptGeneration
2024-03-02 13:54:54 [INFO] Executing Step 2: CodeGenerator
2024-03-02 13:54:54 [INFO] Executing Step 3: CachePopulation
2024-03-02 13:54:54 [INFO] Executing Step 4: CodeExecution
2024-03-02 13:54:54 [INFO] Saving charts to C:\Users\mram\OneDrive - Intel Corporation\Python\OpenAI\ChatFun\exports\charts\temp_chart.png
2024-03-02 13:54:54 [INFO] 
Code running:
```
price = dfs[0].loc['2024-01-01', 'Close']
result = {'type': 'number', 'value': price}
        ```
2024-03-02 13:54:54 [WARNING] Failed to execute code with a correction framework [retry number: 1]
2024-03-02 13:54:54 [ERROR] Failed with error: Traceback (most recent call last):
  File "pandas\_libs\index.pyx", line 548, in pandas._libs.index.DatetimeEngine.get_loc
  File "pandas\_libs\hashtable_class_helper.pxi", line 2263, in pandas._libs.hashtable.Int64HashTable.get_item
  File "pandas\_libs\hashtable_class_helper.pxi", line 2273, in pandas._libs.hashtable.Int64HashTable.get_item
KeyError: 1704067200000000000

During handling of the above exception, another exception occurred:

Traceback (most recent call last):
  File "C:\Users\mram\AppData\Local\Packages\PythonSoftwareFoundation.Python.3.10_qbz5n2kfra8p0\LocalCache\local-packages\Python310\site-packages\pandas\core\indexes\base.py", line 3802, in get_loc
    return self._engine.get_loc(casted_key)
  File "pandas\_libs\index.pyx", line 516, in pandas._libs.index.DatetimeEngine.get_loc
  File "pandas\_libs\index.pyx", line 550, in pandas._libs.index.DatetimeEngine.get_loc
KeyError: Timestamp('2024-01-01 00:00:00')

The above exception was the direct cause of the following exception:

Traceback (most recent call last):
  File "C:\Users\mram\AppData\Local\Packages\PythonSoftwareFoundation.Python.3.10_qbz5n2kfra8p0\LocalCache\local-packages\Python310\site-packages\pandas\core\indexes\datetimes.py", line 736, in get_loc
    return Index.get_loc(self, key, method, tolerance)
  File "C:\Users\mram\AppData\Local\Packages\PythonSoftwareFoundation.Python.3.10_qbz5n2kfra8p0\LocalCache\local-packages\Python310\site-packages\pandas\core\indexes\base.py", line 3804, in get_loc
    raise KeyError(key) from err
KeyError: Timestamp('2024-01-01 00:00:00')

The above exception was the direct cause of the following exception:

Traceback (most recent call last):
  File "C:\Users\mram\AppData\Local\Packages\PythonSoftwareFoundation.Python.3.10_qbz5n2kfra8p0\LocalCache\local-packages\Python310\site-packages\pandasai\pipelines\smart_datalake_chat\code_execution.py", line 46, in execute
    result = pipeline_context.query_exec_tracker.execute_func(
  File "C:\Users\mram\AppData\Local\Packages\PythonSoftwareFoundation.Python.3.10_qbz5n2kfra8p0\LocalCache\local-packages\Python310\site-packages\pandasai\helpers\query_exec_tracker.py", line 128, in execute_func
    result = function(*args, **kwargs)
  File "C:\Users\mram\AppData\Local\Packages\PythonSoftwareFoundation.Python.3.10_qbz5n2kfra8p0\LocalCache\local-packages\Python310\site-packages\pandasai\helpers\code_manager.py", line 207, in execute_code
    exec(code_to_run, environment)
  File "<string>", line 1, in <module>
  File "C:\Users\mram\AppData\Local\Packages\PythonSoftwareFoundation.Python.3.10_qbz5n2kfra8p0\LocalCache\local-packages\Python310\site-packages\pandas\core\indexing.py", line 1067, in __getitem__
    return self._getitem_tuple(key)
  File "C:\Users\mram\AppData\Local\Packages\PythonSoftwareFoundation.Python.3.10_qbz5n2kfra8p0\LocalCache\local-packages\Python310\site-packages\pandas\core\indexing.py", line 1247, in _getitem_tuple
    return self._getitem_lowerdim(tup)
  File "C:\Users\mram\AppData\Local\Packages\PythonSoftwareFoundation.Python.3.10_qbz5n2kfra8p0\LocalCache\local-packages\Python310\site-packages\pandas\core\indexing.py", line 967, in _getitem_lowerdim
    section = self._getitem_axis(key, axis=i)
  File "C:\Users\mram\AppData\Local\Packages\PythonSoftwareFoundation.Python.3.10_qbz5n2kfra8p0\LocalCache\local-packages\Python310\site-packages\pandas\core\indexing.py", line 1312, in _getitem_axis
    return self._get_label(key, axis=axis)
  File "C:\Users\mram\AppData\Local\Packages\PythonSoftwareFoundation.Python.3.10_qbz5n2kfra8p0\LocalCache\local-packages\Python310\site-packages\pandas\core\indexing.py", line 1260, in _get_label
    return self.obj.xs(label, axis=axis)
  File "C:\Users\mram\AppData\Local\Packages\PythonSoftwareFoundation.Python.3.10_qbz5n2kfra8p0\LocalCache\local-packages\Python310\site-packages\pandas\core\generic.py", line 4056, in xs
    loc = index.get_loc(key)
  File "C:\Users\mram\AppData\Local\Packages\PythonSoftwareFoundation.Python.3.10_qbz5n2kfra8p0\LocalCache\local-packages\Python310\site-packages\pandas\core\indexes\datetimes.py", line 738, in get_loc
    raise KeyError(orig_key) from err
KeyError: '2024-01-01'
. Retrying
2024-03-02 13:54:54 [INFO] Using prompt: <dataframe>
dfs[0]:20x6
Open,High,Low,Close,Adj Close,Volume
42.70000076293945,42.779998779296875,42.13999938964844,9415266544,5327637911,34068200
43.0,43.13999938964844,41.599998474121094,7701600559,5256028827,53669900
42.619998931884766,43.150001525878906,42.43000030517578,1215247101,0859303754,28890300
</dataframe>

The user asked the following question:
Q: What was the price on 2024-01-01?

You generated this python code:
# TODO: import the required dependencies
import pandas as pd

# Write code here
price = dfs[0].loc['2024-01-01', 'Close']

# Declare result var
result = {
    "type": "number",
    "value": price
}

It fails with the following error:
Traceback (most recent call last):
  File "pandas\_libs\index.pyx", line 548, in pandas._libs.index.DatetimeEngine.get_loc
  File "pandas\_libs\hashtable_class_helper.pxi", line 2263, in pandas._libs.hashtable.Int64HashTable.get_item
  File "pandas\_libs\hashtable_class_helper.pxi", line 2273, in pandas._libs.hashtable.Int64HashTable.get_item
KeyError: 1704067200000000000

During handling of the above exception, another exception occurred:

Traceback (most recent call last):
  File "C:\Users\mram\AppData\Local\Packages\PythonSoftwareFoundation.Python.3.10_qbz5n2kfra8p0\LocalCache\local-packages\Python310\site-packages\pandas\core\indexes\base.py", line 3802, in get_loc
    return self._engine.get_loc(casted_key)
  File "pandas\_libs\index.pyx", line 516, in pandas._libs.index.DatetimeEngine.get_loc
  File "pandas\_libs\index.pyx", line 550, in pandas._libs.index.DatetimeEngine.get_loc
KeyError: Timestamp('2024-01-01 00:00:00')

The above exception was the direct cause of the following exception:

Traceback (most recent call last):
  File "C:\Users\mram\AppData\Local\Packages\PythonSoftwareFoundation.Python.3.10_qbz5n2kfra8p0\LocalCache\local-packages\Python310\site-packages\pandas\core\indexes\datetimes.py", line 736, in get_loc
    return Index.get_loc(self, key, method, tolerance)
  File "C:\Users\mram\AppData\Local\Packages\PythonSoftwareFoundation.Python.3.10_qbz5n2kfra8p0\LocalCache\local-packages\Python310\site-packages\pandas\core\indexes\base.py", line 3804, in get_loc
    raise KeyError(key) from err
KeyError: Timestamp('2024-01-01 00:00:00')

The above exception was the direct cause of the following exception:

Traceback (most recent call last):
  File "C:\Users\mram\AppData\Local\Packages\PythonSoftwareFoundation.Python.3.10_qbz5n2kfra8p0\LocalCache\local-packages\Python310\site-packages\pandasai\pipelines\smart_datalake_chat\code_execution.py", line 46, in execute
    result = pipeline_context.query_exec_tracker.execute_func(
  File "C:\Users\mram\AppData\Local\Packages\PythonSoftwareFoundation.Python.3.10_qbz5n2kfra8p0\LocalCache\local-packages\Python310\site-packages\pandasai\helpers\query_exec_tracker.py", line 128, in execute_func
    result = function(*args, **kwargs)
  File "C:\Users\mram\AppData\Local\Packages\PythonSoftwareFoundation.Python.3.10_qbz5n2kfra8p0\LocalCache\local-packages\Python310\site-packages\pandasai\helpers\code_manager.py", line 207, in execute_code
    exec(code_to_run, environment)
  File "<string>", line 1, in <module>
  File "C:\Users\mram\AppData\Local\Packages\PythonSoftwareFoundation.Python.3.10_qbz5n2kfra8p0\LocalCache\local-packages\Python310\site-packages\pandas\core\indexing.py", line 1067, in __getitem__
    return self._getitem_tuple(key)
  File "C:\Users\mram\AppData\Local\Packages\PythonSoftwareFoundation.Python.3.10_qbz5n2kfra8p0\LocalCache\local-packages\Python310\site-packages\pandas\core\indexing.py", line 1247, in _getitem_tuple
    return self._getitem_lowerdim(tup)
  File "C:\Users\mram\AppData\Local\Packages\PythonSoftwareFoundation.Python.3.10_qbz5n2kfra8p0\LocalCache\local-packages\Python310\site-packages\pandas\core\indexing.py", line 967, in _getitem_lowerdim
    section = self._getitem_axis(key, axis=i)
  File "C:\Users\mram\AppData\Local\Packages\PythonSoftwareFoundation.Python.3.10_qbz5n2kfra8p0\LocalCache\local-packages\Python310\site-packages\pandas\core\indexing.py", line 1312, in _getitem_axis
    return self._get_label(key, axis=axis)
  File "C:\Users\mram\AppData\Local\Packages\PythonSoftwareFoundation.Python.3.10_qbz5n2kfra8p0\LocalCache\local-packages\Python310\site-packages\pandas\core\indexing.py", line 1260, in _get_label
    return self.obj.xs(label, axis=axis)
  File "C:\Users\mram\AppData\Local\Packages\PythonSoftwareFoundation.Python.3.10_qbz5n2kfra8p0\LocalCache\local-packages\Python310\site-packages\pandas\core\generic.py", line 4056, in xs
    loc = index.get_loc(key)
  File "C:\Users\mram\AppData\Local\Packages\PythonSoftwareFoundation.Python.3.10_qbz5n2kfra8p0\LocalCache\local-packages\Python310\site-packages\pandas\core\indexes\datetimes.py", line 738, in get_loc
    raise KeyError(orig_key) from err
KeyError: '2024-01-01'


Fix the python code above and return the new python code:
2024-03-02 13:54:56 [INFO] HTTP Request: POST https://api.openai.com/v1/chat/completions "HTTP/1.1 200 OK"
2024-03-02 13:54:56 [INFO] Saving charts to C:\Users\mram\OneDrive - Intel Corporation\Python\OpenAI\ChatFun\exports\charts\temp_chart.png
2024-03-02 13:54:56 [INFO] 
Code running:
```
price = dfs[0].loc['2024-01-01', 'Close']
result = {'type': 'number', 'value': price}
        ```
2024-03-02 13:54:56 [WARNING] Failed to execute code with a correction framework [retry number: 2]
2024-03-02 13:54:56 [ERROR] Failed with error: Traceback (most recent call last):
  File "pandas\_libs\index.pyx", line 548, in pandas._libs.index.DatetimeEngine.get_loc
  File "pandas\_libs\hashtable_class_helper.pxi", line 2263, in pandas._libs.hashtable.Int64HashTable.get_item
  File "pandas\_libs\hashtable_class_helper.pxi", line 2273, in pandas._libs.hashtable.Int64HashTable.get_item
KeyError: 1704067200000000000

During handling of the above exception, another exception occurred:

Traceback (most recent call last):
  File "C:\Users\mram\AppData\Local\Packages\PythonSoftwareFoundation.Python.3.10_qbz5n2kfra8p0\LocalCache\local-packages\Python310\site-packages\pandas\core\indexes\base.py", line 3802, in get_loc
    return self._engine.get_loc(casted_key)
  File "pandas\_libs\index.pyx", line 516, in pandas._libs.index.DatetimeEngine.get_loc
  File "pandas\_libs\index.pyx", line 550, in pandas._libs.index.DatetimeEngine.get_loc
KeyError: Timestamp('2024-01-01 00:00:00')

The above exception was the direct cause of the following exception:

Traceback (most recent call last):
  File "C:\Users\mram\AppData\Local\Packages\PythonSoftwareFoundation.Python.3.10_qbz5n2kfra8p0\LocalCache\local-packages\Python310\site-packages\pandas\core\indexes\datetimes.py", line 736, in get_loc
    return Index.get_loc(self, key, method, tolerance)
  File "C:\Users\mram\AppData\Local\Packages\PythonSoftwareFoundation.Python.3.10_qbz5n2kfra8p0\LocalCache\local-packages\Python310\site-packages\pandas\core\indexes\base.py", line 3804, in get_loc
    raise KeyError(key) from err
KeyError: Timestamp('2024-01-01 00:00:00')

The above exception was the direct cause of the following exception:

Traceback (most recent call last):
  File "C:\Users\mram\AppData\Local\Packages\PythonSoftwareFoundation.Python.3.10_qbz5n2kfra8p0\LocalCache\local-packages\Python310\site-packages\pandasai\pipelines\smart_datalake_chat\code_execution.py", line 46, in execute
    result = pipeline_context.query_exec_tracker.execute_func(
  File "C:\Users\mram\AppData\Local\Packages\PythonSoftwareFoundation.Python.3.10_qbz5n2kfra8p0\LocalCache\local-packages\Python310\site-packages\pandasai\helpers\query_exec_tracker.py", line 128, in execute_func
    result = function(*args, **kwargs)
  File "C:\Users\mram\AppData\Local\Packages\PythonSoftwareFoundation.Python.3.10_qbz5n2kfra8p0\LocalCache\local-packages\Python310\site-packages\pandasai\helpers\code_manager.py", line 207, in execute_code
    exec(code_to_run, environment)
  File "<string>", line 1, in <module>
  File "C:\Users\mram\AppData\Local\Packages\PythonSoftwareFoundation.Python.3.10_qbz5n2kfra8p0\LocalCache\local-packages\Python310\site-packages\pandas\core\indexing.py", line 1067, in __getitem__
    return self._getitem_tuple(key)
  File "C:\Users\mram\AppData\Local\Packages\PythonSoftwareFoundation.Python.3.10_qbz5n2kfra8p0\LocalCache\local-packages\Python310\site-packages\pandas\core\indexing.py", line 1247, in _getitem_tuple
    return self._getitem_lowerdim(tup)
  File "C:\Users\mram\AppData\Local\Packages\PythonSoftwareFoundation.Python.3.10_qbz5n2kfra8p0\LocalCache\local-packages\Python310\site-packages\pandas\core\indexing.py", line 967, in _getitem_lowerdim
    section = self._getitem_axis(key, axis=i)
  File "C:\Users\mram\AppData\Local\Packages\PythonSoftwareFoundation.Python.3.10_qbz5n2kfra8p0\LocalCache\local-packages\Python310\site-packages\pandas\core\indexing.py", line 1312, in _getitem_axis
    return self._get_label(key, axis=axis)
  File "C:\Users\mram\AppData\Local\Packages\PythonSoftwareFoundation.Python.3.10_qbz5n2kfra8p0\LocalCache\local-packages\Python310\site-packages\pandas\core\indexing.py", line 1260, in _get_label
    return self.obj.xs(label, axis=axis)
  File "C:\Users\mram\AppData\Local\Packages\PythonSoftwareFoundation.Python.3.10_qbz5n2kfra8p0\LocalCache\local-packages\Python310\site-packages\pandas\core\generic.py", line 4056, in xs
    loc = index.get_loc(key)
  File "C:\Users\mram\AppData\Local\Packages\PythonSoftwareFoundation.Python.3.10_qbz5n2kfra8p0\LocalCache\local-packages\Python310\site-packages\pandas\core\indexes\datetimes.py", line 738, in get_loc
    raise KeyError(orig_key) from err
KeyError: '2024-01-01'
. Retrying
2024-03-02 13:54:56 [INFO] Using prompt: <dataframe>
dfs[0]:20x6
Open,High,Low,Close,Adj Close,Volume
42.70000076293945,42.779998779296875,42.13999938964844,9415266544,5327637911,34068200
43.0,43.13999938964844,41.599998474121094,7701600559,5256028827,53669900
42.619998931884766,43.150001525878906,42.43000030517578,1215247101,0859303754,28890300
</dataframe>

The user asked the following question:
Q: What was the price on 2024-01-01?

You generated this python code:
# TODO: import the required dependencies
import pandas as pd

# Write code here
price = dfs[0].loc['2024-01-01', 'Close']

# Declare result var
result = {
    "type": "number",
    "value": price
}

It fails with the following error:
Traceback (most recent call last):
  File "pandas\_libs\index.pyx", line 548, in pandas._libs.index.DatetimeEngine.get_loc
  File "pandas\_libs\hashtable_class_helper.pxi", line 2263, in pandas._libs.hashtable.Int64HashTable.get_item
  File "pandas\_libs\hashtable_class_helper.pxi", line 2273, in pandas._libs.hashtable.Int64HashTable.get_item
KeyError: 1704067200000000000

During handling of the above exception, another exception occurred:

Traceback (most recent call last):
  File "C:\Users\mram\AppData\Local\Packages\PythonSoftwareFoundation.Python.3.10_qbz5n2kfra8p0\LocalCache\local-packages\Python310\site-packages\pandas\core\indexes\base.py", line 3802, in get_loc
    return self._engine.get_loc(casted_key)
  File "pandas\_libs\index.pyx", line 516, in pandas._libs.index.DatetimeEngine.get_loc
  File "pandas\_libs\index.pyx", line 550, in pandas._libs.index.DatetimeEngine.get_loc
KeyError: Timestamp('2024-01-01 00:00:00')

The above exception was the direct cause of the following exception:

Traceback (most recent call last):
  File "C:\Users\mram\AppData\Local\Packages\PythonSoftwareFoundation.Python.3.10_qbz5n2kfra8p0\LocalCache\local-packages\Python310\site-packages\pandas\core\indexes\datetimes.py", line 736, in get_loc
    return Index.get_loc(self, key, method, tolerance)
  File "C:\Users\mram\AppData\Local\Packages\PythonSoftwareFoundation.Python.3.10_qbz5n2kfra8p0\LocalCache\local-packages\Python310\site-packages\pandas\core\indexes\base.py", line 3804, in get_loc
    raise KeyError(key) from err
KeyError: Timestamp('2024-01-01 00:00:00')

The above exception was the direct cause of the following exception:

Traceback (most recent call last):
  File "C:\Users\mram\AppData\Local\Packages\PythonSoftwareFoundation.Python.3.10_qbz5n2kfra8p0\LocalCache\local-packages\Python310\site-packages\pandasai\pipelines\smart_datalake_chat\code_execution.py", line 46, in execute
    result = pipeline_context.query_exec_tracker.execute_func(
  File "C:\Users\mram\AppData\Local\Packages\PythonSoftwareFoundation.Python.3.10_qbz5n2kfra8p0\LocalCache\local-packages\Python310\site-packages\pandasai\helpers\query_exec_tracker.py", line 128, in execute_func
    result = function(*args, **kwargs)
  File "C:\Users\mram\AppData\Local\Packages\PythonSoftwareFoundation.Python.3.10_qbz5n2kfra8p0\LocalCache\local-packages\Python310\site-packages\pandasai\helpers\code_manager.py", line 207, in execute_code
    exec(code_to_run, environment)
  File "<string>", line 1, in <module>
  File "C:\Users\mram\AppData\Local\Packages\PythonSoftwareFoundation.Python.3.10_qbz5n2kfra8p0\LocalCache\local-packages\Python310\site-packages\pandas\core\indexing.py", line 1067, in __getitem__
    return self._getitem_tuple(key)
  File "C:\Users\mram\AppData\Local\Packages\PythonSoftwareFoundation.Python.3.10_qbz5n2kfra8p0\LocalCache\local-packages\Python310\site-packages\pandas\core\indexing.py", line 1247, in _getitem_tuple
    return self._getitem_lowerdim(tup)
  File "C:\Users\mram\AppData\Local\Packages\PythonSoftwareFoundation.Python.3.10_qbz5n2kfra8p0\LocalCache\local-packages\Python310\site-packages\pandas\core\indexing.py", line 967, in _getitem_lowerdim
    section = self._getitem_axis(key, axis=i)
  File "C:\Users\mram\AppData\Local\Packages\PythonSoftwareFoundation.Python.3.10_qbz5n2kfra8p0\LocalCache\local-packages\Python310\site-packages\pandas\core\indexing.py", line 1312, in _getitem_axis
    return self._get_label(key, axis=axis)
  File "C:\Users\mram\AppData\Local\Packages\PythonSoftwareFoundation.Python.3.10_qbz5n2kfra8p0\LocalCache\local-packages\Python310\site-packages\pandas\core\indexing.py", line 1260, in _get_label
    return self.obj.xs(label, axis=axis)
  File "C:\Users\mram\AppData\Local\Packages\PythonSoftwareFoundation.Python.3.10_qbz5n2kfra8p0\LocalCache\local-packages\Python310\site-packages\pandas\core\generic.py", line 4056, in xs
    loc = index.get_loc(key)
  File "C:\Users\mram\AppData\Local\Packages\PythonSoftwareFoundation.Python.3.10_qbz5n2kfra8p0\LocalCache\local-packages\Python310\site-packages\pandas\core\indexes\datetimes.py", line 738, in get_loc
    raise KeyError(orig_key) from err
KeyError: '2024-01-01'


Fix the python code above and return the new python code:
2024-03-02 13:54:57 [INFO] HTTP Request: POST https://api.openai.com/v1/chat/completions "HTTP/1.1 200 OK"
2024-03-02 13:54:57 [INFO] Saving charts to C:\Users\mram\OneDrive - Intel Corporation\Python\OpenAI\ChatFun\exports\charts\temp_chart.png
2024-03-02 13:54:57 [INFO] 
Code running:
```
price = dfs[0].loc['2024-01-01', 'Close']
result = {'type': 'number', 'value': price}
        ```
2024-03-02 13:54:57 [ERROR] Pipeline failed on step 4: '2024-01-01'
2024-03-02 13:57:14 [INFO] Question: What was the price on 2024-02-02?
2024-03-02 13:57:14 [INFO] Running PandasAI with openai LLM...
2024-03-02 13:57:14 [INFO] Prompt ID: 74e75aac-ca11-4c39-978e-b99d23a7371e
2024-03-02 13:57:14 [INFO] Executing Step 0: CacheLookup
2024-03-02 13:57:14 [INFO] Executing Step 1: PromptGeneration
2024-03-02 13:57:14 [INFO] Using prompt: <dataframe>
dfs[0]:20x6
Open,High,Low,Close,Adj Close,Volume
42.619998931884766,43.150001525878906,42.43000030517578,42.77000045776367,42.64500045776367,28890300
42.70000076293945,42.779998779296875,42.13999938964844,42.7400016784668,42.7400016784668,34068200
43.0,43.13999938964844,41.599998474121094,42.599998474121094,42.475494384765625,53669900
</dataframe>




Update this initial code:
```python
# TODO: import the required dependencies
import pandas as pd

# Write code here

# Declare result var: type (possible values "string", "number", "dataframe", "plot"). Examples: { "type": "string", "value": f"The highest salary is {highest_salary}." } or { "type": "number", "value": 125 } or { "type": "dataframe", "value": pd.DataFrame({...}) } or { "type": "plot", "value": "temp_chart.png" }
```

Q: What was the price on 2024-02-02?
Variable `dfs: list[pd.DataFrame]` is already declared.

At the end, declare "result" variable as a dictionary of type and value.



Generate python code and return full updated code:
2024-03-02 13:57:14 [INFO] Executing Step 2: CodeGenerator
2024-03-02 13:57:16 [INFO] HTTP Request: POST https://api.openai.com/v1/chat/completions "HTTP/1.1 200 OK"
2024-03-02 13:57:16 [INFO] Code generated:
            ```
            # TODO: import the required dependencies
import pandas as pd

# Write code here
date = "2024-02-02"
price = None
for df in dfs:
    if date in df.index:
        price = df.loc[date, 'Close']
        break

result = {"type": "number", "value": price}
            ```
            
2024-03-02 13:57:16 [INFO] Executing Step 3: CachePopulation
2024-03-02 13:57:16 [INFO] Executing Step 4: CodeExecution
2024-03-02 13:57:16 [INFO] Saving charts to C:\Users\mram\OneDrive - Intel Corporation\Python\OpenAI\ChatFun\exports\charts\temp_chart.png
2024-03-02 13:57:16 [INFO] 
Code running:
```
date = '2024-02-02'
price = None
for df in dfs:
    if date in df.index:
        price = df.loc[date, 'Close']
        break
result = {'type': 'number', 'value': price}
        ```
2024-03-02 13:57:16 [INFO] Executing Step 5: ResultValidation
2024-03-02 13:57:16 [INFO] Answer: {'type': 'number', 'value': 42.599998474121094}
2024-03-02 13:57:16 [INFO] Executed in: 1.992943286895752s
2024-03-02 13:57:16 [INFO] Executing Step 6: ResultParsing
2024-03-02 13:57:35 [INFO] Question: What was the average price?
2024-03-02 13:57:35 [INFO] Running PandasAI with openai LLM...
2024-03-02 13:57:35 [INFO] Prompt ID: 3c4c9234-8a09-488a-9550-105c321d33b8
2024-03-02 13:57:35 [INFO] Executing Step 0: CacheLookup
2024-03-02 13:57:35 [INFO] Executing Step 1: PromptGeneration
2024-03-02 13:57:35 [INFO] Using prompt: <dataframe>
dfs[0]:20x6
Open,High,Low,Close,Adj Close,Volume
42.619998931884766,43.150001525878906,42.43000030517578,42.77000045776367,42.64500045776367,28890300
43.0,43.13999938964844,41.599998474121094,42.599998474121094,42.475494384765625,53669900
42.70000076293945,42.779998779296875,42.13999938964844,42.7400016784668,42.7400016784668,34068200
</dataframe>




Update this initial code:
```python
# TODO: import the required dependencies
import pandas as pd

# Write code here

# Declare result var: type (possible values "string", "number", "dataframe", "plot"). Examples: { "type": "string", "value": f"The highest salary is {highest_salary}." } or { "type": "number", "value": 125 } or { "type": "dataframe", "value": pd.DataFrame({...}) } or { "type": "plot", "value": "temp_chart.png" }
```

Q: What was the average price?
Variable `dfs: list[pd.DataFrame]` is already declared.

At the end, declare "result" variable as a dictionary of type and value.



Generate python code and return full updated code:
2024-03-02 13:57:35 [INFO] Executing Step 2: CodeGenerator
2024-03-02 13:57:36 [INFO] HTTP Request: POST https://api.openai.com/v1/chat/completions "HTTP/1.1 200 OK"
2024-03-02 13:57:36 [INFO] Code generated:
            ```
            # TODO: import the required dependencies
import pandas as pd

# Write code here
average_price = sum([df['Close'].mean() for df in dfs]) / len(dfs)

# Declare result var
result = {"type": "number", "value": average_price}
            ```
            
2024-03-02 13:57:36 [INFO] Executing Step 3: CachePopulation
2024-03-02 13:57:36 [INFO] Executing Step 4: CodeExecution
2024-03-02 13:57:36 [INFO] Saving charts to C:\Users\mram\OneDrive - Intel Corporation\Python\OpenAI\ChatFun\exports\charts\temp_chart.png
2024-03-02 13:57:36 [INFO] 
Code running:
```
average_price = sum([df['Close'].mean() for df in dfs]) / len(dfs)
result = {'type': 'number', 'value': average_price}
        ```
2024-03-02 13:57:36 [INFO] Executing Step 5: ResultValidation
2024-03-02 13:57:36 [INFO] Answer: {'type': 'number', 'value': 43.20900001525879}
2024-03-02 13:57:36 [INFO] Executed in: 1.3809468746185303s
2024-03-02 13:57:36 [INFO] Executing Step 6: ResultParsing
